Workbook

Sheet control
A1: VEHIDCODE | B1: FILENAMES_EXPECTED | C1: SAVE_TO | D1: VEHID_ID_CATEGORY | E1: VEHID_ID | F1: ENGLISH | G1: WEB | H1: IS_POWERED_UNPOWERED_SUNDRY | I1: IS_WAGON_OR_COACH | J1: TRACK_TYPES | K1: PROPERTIES | L1: ROSTER | M1: GRAPHICS_PROPERTIES | N1: ITEM | O1: NAME | P1: CONCEPT_READONLY | Q1: EXCLUDE_READONLY | R1: TPL_READONLY
A2: mglv_Maglev_Wagon_Powered | B2: =_xlfn.TEXTAFTER(CONTROL[[#This Row],[VEHIDCODE]],"_") -> Maglev_Wagon_Powered | C2: {="src\"&(_xlfn.LET(_xlpm.l,SUBSTITUTE(CONTROL[[#This Row],[VEHID_ID_CATEGORY]],"ID_RANGE_",""),_xlfn.IFS( _xlpm.l="RBS","Railbus\Railbus_Steam", _xlpm.l="RBD","Railbus\Railbus_Diesel", _xlpm.l="RBE","Railbus\Railbus_Electric", _xlpm.l="RBM","Railbus\Railbus_Maglev", _xlpm.l="STEAM","Steam", _xlpm.l="DIESEL","Diesel", OR(_xlpm.l="ELECTRIC", _xlpm.l="MULTIMETRO"),"Electric", _xlpm.l="MAGLEV","Maglev", _xlpm.l="MULTIMAGLEV","MMU", _xlpm.l="CARGODMU","CargoDMU", _xlpm.l="DMU","DMU", _xlpm.l="CARGOEMU","CargoEMU", _xlpm.l="EMU","EMU", _xlpm.l="MMU","MMU", _xlpm.l="SINGLEMETRO","Single_Metro", OR(ISNUMBER(SEARCH("_powered",CONTROL[[#This Row],[VEHIDCODE]])),ISNUMBER(SEARCH("_unpowered",CONTROL[[#This Row],[VEHIDCODE]]))),"Special", _xlpm.l="WAGONS","wagons\"&SUBSTITUTE(_xlfn.TEXTBEFORE(SUBSTITUTE(_xlfn.TEXTAFTER(CONTROL[[#This Row],[VEHIDCODE]],"_",2),"Service_Car","Service#Car"),"_"),"#","_"), _xlpm.l="WAGONS_MGLV","Wagons_Maglev\"&_xlfn.TEXTBEFORE(_xlfn.TEXTAFTER(CONTROL[[#This Row],[VEHIDCODE]],"_",2),"_"), _xlpm.l="COACHES","Coaches\"&_xlfn.TEXTBEFORE(_xlfn.TEXTAFTER(CONTROL[[#This Row],[VEHIDCODE]],"_",2),"_"), _xlpm.l="COACHES_MGLV","Coaches_Maglev\"&_xlfn.TEXTBEFORE(_xlfn.TEXTAFTER(CONTROL[[#This Row],[VEHIDCODE]],"_",2),"_") )))} -> src\Special | D2: {="ID_RANGE_"&_xlfn.IFS( ISNUMBER(SEARCH("mglv_maglev_wagon",CONTROL[[#This Row],[VEHIDCODE]])),"UNIT_WAGONS_MGLV", ISNUMBER(SEARCH("mu_mu_cargo_wagon",CONTROL[[#This Row],[VEHIDCODE]])),"UNIT_WAGONS_RAIL_CARGO", ISNUMBER(SEARCH("mtro_metro_wagon_",CONTROL[[#This Row],[VEHIDCODE]])),"UNIT_WAGONS_MTRO", ISNUMBER(SEARCH("mu_mu_wagon",CONTROL[[#This Row],[VEHIDCODE]])),"UNIT_WAGONS_RAIL", ISNUMBER(SEARCH("mu_wagon",CONTROL[[#This Row],[VEHIDCODE]])),"WAGONS", ISNUMBER(SEARCH("mu_coach",CONTROL[[#This Row],[VEHIDCODE]])),"COACHES", ISNUMBER(SEARCH("mglv_coach",CONTROL[[#This Row],[VEHIDCODE]])),"COACHES_MGLV", _xlfn.TEXTBEFORE(CONTROL[[#This Row],[VEHIDCODE]],"_")="rbs","RBS", _xlfn.TEXTBEFORE(CONTROL[[#This Row],[VEHIDCODE]],"_")="rbd","RBD", _xlfn.TEXTBEFORE(CONTROL[[#This Row],[VEHIDCODE]],"_")="rbe","RBE", _xlfn.TEXTBEFORE(CONTROL[[#This Row],[VEHIDCODE]],"_")="rbm","RBM", _xlfn.TEXTBEFORE(CONTROL[[#This Row],[VEHIDCODE]],"_")="steam","STEAM", _xlfn.TEXTBEFORE(CONTROL[[#This Row],[VEHIDCODE]],"_")="diesel","DIESEL", _xlfn.TEXTBEFORE(CONTROL[[#This Row],[VEHIDCODE]],"_")="electric","ELECTRIC", _xlfn.TEXTBEFORE(CONTROL[[#This Row],[VEHIDCODE]],"_")="mtro","MULTIMETRO", _xlfn.TEXTBEFORE(CONTROL[[#This Row],[VEHIDCODE]],"_")="singlemtro","SINGLEMETRO", _xlfn.TEXTBEFORE(CONTROL[[#This Row],[VEHIDCODE]],"_")="dmu","DMU", _xlfn.TEXTBEFORE(CONTROL[[#This Row],[VEHIDCODE]],"_")="cargodmu","CARGODMU", _xlfn.TEXTBEFORE(CONTROL[[#This Row],[VEHIDCODE]],"_")="emu","EMU", _xlfn.TEXTBEFORE(CONTROL[[#This Row],[VEHIDCODE]],"_")="cargoemu","CARGOEMU", _xlfn.TEXTBEFORE(CONTROL[[#This Row],[VEHIDCODE]],"_",2)="mglv_Wagon","WAGONS_MGLV", AND(_xlfn.TEXTBEFORE(CONTROL[[#This Row],[VEHIDCODE]],"_",1)="mglv",_xlfn.XLOOKUP(CONTROL[[#This Row],[VEHIDCODE]],PROPERTIES[VEHIDCODE],PROPERTIES[DUAL_HEADED])=0),"MAGLEV", _xlfn.TEXTBEFORE(CONTROL[[#This Row],[VEHIDCODE]],"_")="mmu","MMU")} -> ID_RANGE_UNIT_WAGONS_MGLV | E2: 13005 | F2: Maglev Unit Wagon | G2: NA | H2: =AND(CONTROL[[#This Row],[IS_WAGON_OR_COACH]]=TRUE,OR(RIGHT(CONTROL[[#This Row],[VEHIDCODE]],7)="Powered",RIGHT(CONTROL[[#This Row],[VEHIDCODE]],9)="Unpowered")) -> TRUE | I2: =OR(ISNUMBER(SEARCH("_wagon_powered",CONTROL[[#This Row],[VEHIDCODE]])),ISNUMBER(SEARCH("_wagon_unpowered",CONTROL[[#This Row],[VEHIDCODE]])),ISNUMBER(SEARCH("mu_wagon_",CONTROL[[#This Row],[VEHIDCODE]])),ISNUMBER(SEARCH("mglv_wagon_",CONTROL[[#This Row],[VEHIDCODE]])),ISNUMBER(SEARCH("mu_coach_",CONTROL[[#This Row],[VEHIDCODE]])),ISNUMBER(SEARCH("mglv_coach_",CONTROL[[#This Row],[VEHIDCODE]]))) -> TRUE | J2: =ISNUMBER(_xlfn.XMATCH(CONTROL[[#This Row],[VEHIDCODE]],TRACK_TYPES[VEHIDCODE],0)) -> TRUE | K2: =ISNUMBER(_xlfn.XMATCH(CONTROL[[#This Row],[VEHIDCODE]],PROPERTIES[VEHIDCODE],0)) -> TRUE | L2: =ISNUMBER(_xlfn.XLOOKUP(CONTROL[[#This Row],[VEHIDCODE]],roster!A:A,roster!D:D)) -> TRUE | M2: =ISNUMBER(_xlfn.XMATCH(CONTROL[[#This Row],[VEHIDCODE]],GRAPHICS_PROPERTIES[VEHIDCODE],0)) -> TRUE | N2: ="item_"&CONTROL[[#This Row],[VEHIDCODE]] -> item_mglv_Maglev_Wagon_Powered | O2: ="str_"&CONTROL[[#This Row],[VEHIDCODE]] -> str_mglv_Maglev_Wagon_Powered | P2: =_xlfn.XLOOKUP(CONTROL[[#This Row],[VEHIDCODE]],PROPERTIES[VEHIDCODE],PROPERTIES[IS_CONCEPT])="IS_CONCEPT" -> FALSE | Q2: =_xlfn.XLOOKUP(CONTROL[[#This Row],[VEHIDCODE]],PROPERTIES[VEHIDCODE],PROPERTIES[EXCLUDE]) -> FALSE | R2: {=_xlfn.XLOOKUP(CONTROL[[#This Row],[VEHIDCODE]],GRAPHICS_PROPERTIES[VEHIDCODE],GRAPHICS_PROPERTIES[TEMPLATE_ID]&GRAPHICS_PROPERTIES[TEMPLATE_AMENDMENT_CODE])} -> TPL_01F
A3: mglv_Maglev_Wagon_Unpowered | B3: =_xlfn.TEXTAFTER(CONTROL[[#This Row],[VEHIDCODE]],"_") -> Maglev_Wagon_Unpowered | C3: {="src\"&(_xlfn.LET(_xlpm.l,SUBSTITUTE(CONTROL[[#This Row],[VEHID_ID_CATEGORY]],"ID_RANGE_",""),_xlfn.IFS( _xlpm.l="RBS","Railbus\Railbus_Steam", _xlpm.l="RBD","Railbus\Railbus_Diesel", _xlpm.l="RBE","Railbus\Railbus_Electric", _xlpm.l="RBM","Railbus\Railbus_Maglev", _xlpm.l="STEAM","Steam", _xlpm.l="DIESEL","Diesel", OR(_xlpm.l="ELECTRIC", _xlpm.l="MULTIMETRO"),"Electric", _xlpm.l="MAGLEV","Maglev", _xlpm.l="MULTIMAGLEV","MMU", _xlpm.l="CARGODMU","CargoDMU", _xlpm.l="DMU","DMU", _xlpm.l="CARGOEMU","CargoEMU", _xlpm.l="EMU","EMU", _xlpm.l="MMU","MMU", _xlpm.l="SINGLEMETRO","Single_Metro", OR(ISNUMBER(SEARCH("_powered",CONTROL[[#This Row],[VEHIDCODE]])),ISNUMBER(SEARCH("_unpowered",CONTROL[[#This Row],[VEHIDCODE]]))),"Special", _xlpm.l="WAGONS","wagons\"&SUBSTITUTE(_xlfn.TEXTBEFORE(SUBSTITUTE(_xlfn.TEXTAFTER(CONTROL[[#This Row],[VEHIDCODE]],"_",2),"Service_Car","Service#Car"),"_"),"#","_"), _xlpm.l="WAGONS_MGLV","Wagons_Maglev\"&_xlfn.TEXTBEFORE(_xlfn.TEXTAFTER(CONTROL[[#This Row],[VEHIDCODE]],"_",2),"_"), _xlpm.l="COACHES","Coaches\"&_xlfn.TEXTBEFORE(_xlfn.TEXTAFTER(CONTROL[[#This Row],[VEHIDCODE]],"_",2),"_"), _xlpm.l="COACHES_MGLV","Coaches_Maglev\"&_xlfn.TEXTBEFORE(_xlfn.TEXTAFTER(CONTROL[[#This Row],[VEHIDCODE]],"_",2),"_") )))} -> src\Special | D3: {="ID_RANGE_"&_xlfn.IFS( ISNUMBER(SEARCH("mglv_maglev_wagon",CONTROL[[#This Row],[VEHIDCODE]])),"UNIT_WAGONS_MGLV", ISNUMBER(SEARCH("mu_mu_cargo_wagon",CONTROL[[#This Row],[VEHIDCODE]])),"UNIT_WAGONS_RAIL_CARGO", ISNUMBER(SEARCH("mtro_metro_wagon_",CONTROL[[#This Row],[VEHIDCODE]])),"UNIT_WAGONS_MTRO", ISNUMBER(SEARCH("mu_mu_wagon",CONTROL[[#This Row],[VEHIDCODE]])),"UNIT_WAGONS_RAIL", ISNUMBER(SEARCH("mu_wagon",CONTROL[[#This Row],[VEHIDCODE]])),"WAGONS", ISNUMBER(SEARCH("mu_coach",CONTROL[[#This Row],[VEHIDCODE]])),"COACHES", ISNUMBER(SEARCH("mglv_coach",CONTROL[[#This Row],[VEHIDCODE]])),"COACHES_MGLV", _xlfn.TEXTBEFORE(CONTROL[[#This Row],[VEHIDCODE]],"_")="rbs","RBS", _xlfn.TEXTBEFORE(CONTROL[[#This Row],[VEHIDCODE]],"_")="rbd","RBD", _xlfn.TEXTBEFORE(CONTROL[[#This Row],[VEHIDCODE]],"_")="rbe","RBE", _xlfn.TEXTBEFORE(CONTROL[[#This Row],[VEHIDCODE]],"_")="rbm","RBM", _xlfn.TEXTBEFORE(CONTROL[[#This Row],[VEHIDCODE]],"_")="steam","STEAM", _xlfn.TEXTBEFORE(CONTROL[[#This Row],[VEHIDCODE]],"_")="diesel","DIESEL", _xlfn.TEXTBEFORE(CONTROL[[#This Row],[VEHIDCODE]],"_")="electric","ELECTRIC", _xlfn.TEXTBEFORE(CONTROL[[#This Row],[VEHIDCODE]],"_")="mtro","MULTIMETRO", _xlfn.TEXTBEFORE(CONTROL[[#This Row],[VEHIDCODE]],"_")="singlemtro","SINGLEMETRO", _xlfn.TEXTBEFORE(CONTROL[[#This Row],[VEHIDCODE]],"_")="dmu","DMU", _xlfn.TEXTBEFORE(CONTROL[[#This Row],[VEHIDCODE]],"_")="cargodmu","CARGODMU", _xlfn.TEXTBEFORE(CONTROL[[#This Row],[VEHIDCODE]],"_")="emu","EMU", _xlfn.TEXTBEFORE(CONTROL[[#This Row],[VEHIDCODE]],"_")="cargoemu","CARGOEMU", _xlfn.TEXTBEFORE(CONTROL[[#This Row],[VEHIDCODE]],"_",2)="mglv_Wagon","WAGONS_MGLV", AND(_xlfn.TEXTBEFORE(CONTROL[[#This Row],[VEHIDCODE]],"_",1)="mglv",_xlfn.XLOOKUP(CONTROL[[#This Row],[VEHIDCODE]],PROPERTIES[VEHIDCODE],PROPERTIES[DUAL_HEADED])=0),"MAGLEV", _xlfn.TEXTBEFORE(CONTROL[[#This Row],[VEHIDCODE]],"_")="mmu","MMU")} -> ID_RANGE_UNIT_WAGONS_MGLV | E3: 13004 | F3: Maglev Unit Wagon | G3: NA | H3: =AND(CONTROL[[#This Row],[IS_WAGON_OR_COACH]]=TRUE,OR(RIGHT(CONTROL[[#This Row],[VEHIDCODE]],7)="Powered",RIGHT(CONTROL[[#This Row],[VEHIDCODE]],9)="Unpowered")) -> TRUE | I3: =OR(ISNUMBER(SEARCH("_wagon_powered",CONTROL[[#This Row],[VEHIDCODE]])),ISNUMBER(SEARCH("_wagon_unpowered",CONTROL[[#This Row],[VEHIDCODE]])),ISNUMBER(SEARCH("mu_wagon_",CONTROL[[#This Row],[VEHIDCODE]])),ISNUMBER(SEARCH("mglv_wagon_",CONTROL[[#This Row],[VEHIDCODE]])),ISNUMBER(SEARCH("mu_coach_",CONTROL[[#This Row],[VEHIDCODE]])),ISNUMBER(SEARCH("mglv_coach_",CONTROL[[#This Row],[VEHIDCODE]]))) -> TRUE | J3: =ISNUMBER(_xlfn.XMATCH(CONTROL[[#This Row],[VEHIDCODE]],TRACK_TYPES[VEHIDCODE],0)) -> TRUE | K3: =ISNUMBER(_xlfn.XMATCH(CONTROL[[#This Row],[VEHIDCODE]],PROPERTIES[VEHIDCODE],0)) -> TRUE | L3: =ISNUMBER(_xlfn.XLOOKUP(CONTROL[[#This Row],[VEHIDCODE]],roster!A:A,roster!D:D)) -> TRUE | M3: =ISNUMBER(_xlfn.XMATCH(CONTROL[[#This Row],[VEHIDCODE]],GRAPHICS_PROPERTIES[VEHIDCODE],0)) -> TRUE | N3: ="item_"&CONTROL[[#This Row],[VEHIDCODE]] -> item_mglv_Maglev_Wagon_Unpowered | O3: ="str_"&CONTROL[[#This Row],[VEHIDCODE]] -> str_mglv_Maglev_Wagon_Unpowered | P3: =_xlfn.XLOOKUP(CONTROL[[#This Row],[VEHIDCODE]],PROPERTIES[VEHIDCODE],PROPERTIES[IS_CONCEPT])="IS_CONCEPT" -> FALSE | Q3: =_xlfn.XLOOKUP(CONTROL[[#This Row],[VEHIDCODE]],PROPERTIES[VEHIDCODE],PROPERTIES[EXCLUDE]) -> FALSE | R3: {=_xlfn.XLOOKUP(CONTROL[[#This Row],[VEHIDCODE]],GRAPHICS_PROPERTIES[VEHIDCODE],GRAPHICS_PROPERTIES[TEMPLATE_ID]&GRAPHICS_PROPERTIES[TEMPLATE_AMENDMENT_CODE])} -> TPL_01F
A4: rbs_Komarek_NOLB_1 | B4: =_xlfn.TEXTAFTER(CONTROL[[#This Row],[VEHIDCODE]],"_") -> Komarek_NOLB_1 | C4: {="src\"&(_xlfn.LET(_xlpm.l,SUBSTITUTE(CONTROL[[#This Row],[VEHID_ID_CATEGORY]],"ID_RANGE_",""),_xlfn.IFS( _xlpm.l="RBS","Railbus\Railbus_Steam", _xlpm.l="RBD","Railbus\Railbus_Diesel", _xlpm.l="RBE","Railbus\Railbus_Electric", _xlpm.l="RBM","Railbus\Railbus_Maglev", _xlpm.l="STEAM","Steam", _xlpm.l="DIESEL","Diesel", OR(_xlpm.l="ELECTRIC", _xlpm.l="MULTIMETRO"),"Electric", _xlpm.l="MAGLEV","Maglev", _xlpm.l="MULTIMAGLEV","MMU", _xlpm.l="CARGODMU","CargoDMU", _xlpm.l="DMU","DMU", _xlpm.l="CARGOEMU","CargoEMU", _xlpm.l="EMU","EMU", _xlpm.l="MMU","MMU", _xlpm.l="SINGLEMETRO","Single_Metro", OR(ISNUMBER(SEARCH("_powered",CONTROL[[#This Row],[VEHIDCODE]])),ISNUMBER(SEARCH("_unpowered",CONTROL[[#This Row],[VEHIDCODE]]))),"Special", _xlpm.l="WAGONS","wagons\"&SUBSTITUTE(_xlfn.TEXTBEFORE(SUBSTITUTE(_xlfn.TEXTAFTER(CONTROL[[#This Row],[VEHIDCODE]],"_",2),"Service_Car","Service#Car"),"_"),"#","_"), _xlpm.l="WAGONS_MGLV","Wagons_Maglev\"&_xlfn.TEXTBEFORE(_xlfn.TEXTAFTER(CONTROL[[#This Row],[VEHIDCODE]],"_",2),"_"), _xlpm.l="COACHES","Coaches\"&_xlfn.TEXTBEFORE(_xlfn.TEXTAFTER(CONTROL[[#This Row],[VEHIDCODE]],"_",2),"_"), _xlpm.l="COACHES_MGLV","Coaches_Maglev\"&_xlfn.TEXTBEFORE(_xlfn.TEXTAFTER(CONTROL[[#This Row],[VEHIDCODE]],"_",2),"_") )))} -> src\Railbus\Railbus_Steam | D4: {="ID_RANGE_"&_xlfn.IFS( ISNUMBER(SEARCH("mglv_maglev_wagon",CONTROL[[#This Row],[VEHIDCODE]])),"UNIT_WAGONS_MGLV", ISNUMBER(SEARCH("mu_mu_cargo_wagon",CONTROL[[#This Row],[VEHIDCODE]])),"UNIT_WAGONS_RAIL_CARGO", ISNUMBER(SEARCH("mtro_metro_wagon_",CONTROL[[#This Row],[VEHIDCODE]])),"UNIT_WAGONS_MTRO", ISNUMBER(SEARCH("mu_mu_wagon",CONTROL[[#This Row],[VEHIDCODE]])),"UNIT_WAGONS_RAIL", ISNUMBER(SEARCH("mu_wagon",CONTROL[[#This Row],[VEHIDCODE]])),"WAGONS", ISNUMBER(SEARCH("mu_coach",CONTROL[[#This Row],[VEHIDCODE]])),"COACHES", ISNUMBER(SEARCH("mglv_coach",CONTROL[[#This Row],[VEHIDCODE]])),"COACHES_MGLV", _xlfn.TEXTBEFORE(CONTROL[[#This Row],[VEHIDCODE]],"_")="rbs","RBS", _xlfn.TEXTBEFORE(CONTROL[[#This Row],[VEHIDCODE]],"_")="rbd","RBD", _xlfn.TEXTBEFORE(CONTROL[[#This Row],[VEHIDCODE]],"_")="rbe","RBE", _xlfn.TEXTBEFORE(CONTROL[[#This Row],[VEHIDCODE]],"_")="rbm","RBM", _xlfn.TEXTBEFORE(CONTROL[[#This Row],[VEHIDCODE]],"_")="steam","STEAM", _xlfn.TEXTBEFORE(CONTROL[[#This Row],[VEHIDCODE]],"_")="diesel","DIESEL", _xlfn.TEXTBEFORE(CONTROL[[#This Row],[VEHIDCODE]],"_")="electric","ELECTRIC", _xlfn.TEXTBEFORE(CONTROL[[#This Row],[VEHIDCODE]],"_")="mtro","MULTIMETRO", _xlfn.TEXTBEFORE(CONTROL[[#This Row],[VEHIDCODE]],"_")="singlemtro","SINGLEMETRO", _xlfn.TEXTBEFORE(CONTROL[[#This Row],[VEHIDCODE]],"_")="dmu","DMU", _xlfn.TEXTBEFORE(CONTROL[[#This Row],[VEHIDCODE]],"_")="cargodmu","CARGODMU", _xlfn.TEXTBEFORE(CONTROL[[#This Row],[VEHIDCODE]],"_")="emu","EMU", _xlfn.TEXTBEFORE(CONTROL[[#This Row],[VEHIDCODE]],"_")="cargoemu","CARGOEMU", _xlfn.TEXTBEFORE(CONTROL[[#This Row],[VEHIDCODE]],"_",2)="mglv_Wagon","WAGONS_MGLV", AND(_xlfn.TEXTBEFORE(CONTROL[[#This Row],[VEHIDCODE]],"_",1)="mglv",_xlfn.XLOOKUP(CONTROL[[#This Row],[VEHIDCODE]],PROPERTIES[VEHIDCODE],PROPERTIES[DUAL_HEADED])=0),"MAGLEV", _xlfn.TEXTBEFORE(CONTROL[[#This Row],[VEHIDCODE]],"_")="mmu","MMU")} -> ID_RANGE_RBS | E4: 1000 | F4: Komarek NOLB 1 | G4: https://de.wikipedia.org/wiki/N%C3%96LB_1%E2%80%933 | H4: =AND(CONTROL[[#This Row],[IS_WAGON_OR_COACH]]=TRUE,OR(RIGHT(CONTROL[[#This Row],[VEHIDCODE]],7)="Powered",RIGHT(CONTROL[[#This Row],[VEHIDCODE]],9)="Unpowered")) -> FALSE | I4: =OR(ISNUMBER(SEARCH("_wagon_powered",CONTROL[[#This Row],[VEHIDCODE]])),ISNUMBER(SEARCH("_wagon_unpowered",CONTROL[[#This Row],[VEHIDCODE]])),ISNUMBER(SEARCH("mu_wagon_",CONTROL[[#This Row],[VEHIDCODE]])),ISNUMBER(SEARCH("mglv_wagon_",CONTROL[[#This Row],[VEHIDCODE]])),ISNUMBER(SEARCH("mu_coach_",CONTROL[[#This Row],[VEHIDCODE]])),ISNUMBER(SEARCH("mglv_coach_",CONTROL[[#This Row],[VEHIDCODE]]))) -> FALSE | J4: =ISNUMBER(_xlfn.XMATCH(CONTROL[[#This Row],[VEHIDCODE]],TRACK_TYPES[VEHIDCODE],0)) -> TRUE | K4: =ISNUMBER(_xlfn.XMATCH(CONTROL[[#This Row],[VEHIDCODE]],PROPERTIES[VEHIDCODE],0)) -> TRUE | L4: =ISNUMBER(_xlfn.XLOOKUP(CONTROL[[#This Row],[VEHIDCODE]],roster!A:A,roster!D:D)) -> TRUE | M4: =ISNUMBER(_xlfn.XMATCH(CONTROL[[#This Row],[VEHIDCODE]],GRAPHICS_PROPERTIES[VEHIDCODE],0)) -> TRUE | N4: ="item_"&CONTROL[[#This Row],[VEHIDCODE]] -> item_rbs_Komarek_NOLB_1 | O4: ="str_"&CONTROL[[#This Row],[VEHIDCODE]] -> str_rbs_Komarek_NOLB_1 | P4: =_xlfn.XLOOKUP(CONTROL[[#This Row],[VEHIDCODE]],PROPERTIES[VEHIDCODE],PROPERTIES[IS_CONCEPT])="IS_CONCEPT" -> FALSE | Q4: =_xlfn.XLOOKUP(CONTROL[[#This Row],[VEHIDCODE]],PROPERTIES[VEHIDCODE],PROPERTIES[EXCLUDE]) -> FALSE | R4: {=_xlfn.XLOOKUP(CONTROL[[#This Row],[VEHIDCODE]],GRAPHICS_PROPERTIES[VEHIDCODE],GRAPHICS_PROPERTIES[TEMPLATE_ID]&GRAPHICS_PROPERTIES[TEMPLATE_AMENDMENT_CODE])} -> TPL_01B
A5: rbs_Kerr__Stuart___Co__86 | B5: =_xlfn.TEXTAFTER(CONTROL[[#This Row],[VEHIDCODE]],"_") -> Kerr__Stuart___Co__86 | C5: {="src\"&(_xlfn.LET(_xlpm.l,SUBSTITUTE(CONTROL[[#This Row],[VEHID_ID_CATEGORY]],"ID_RANGE_",""),_xlfn.IFS( _xlpm.l="RBS","Railbus\Railbus_Steam", _xlpm.l="RBD","Railbus\Railbus_Diesel", _xlpm.l="RBE","Railbus\Railbus_Electric", _xlpm.l="RBM","Railbus\Railbus_Maglev", _xlpm.l="STEAM","Steam", _xlpm.l="DIESEL","Diesel", OR(_xlpm.l="ELECTRIC", _xlpm.l="MULTIMETRO"),"Electric", _xlpm.l="MAGLEV","Maglev", _xlpm.l="MULTIMAGLEV","MMU", _xlpm.l="CARGODMU","CargoDMU", _xlpm.l="DMU","DMU", _xlpm.l="CARGOEMU","CargoEMU", _xlpm.l="EMU","EMU", _xlpm.l="MMU","MMU", _xlpm.l="SINGLEMETRO","Single_Metro", OR(ISNUMBER(SEARCH("_powered",CONTROL[[#This Row],[VEHIDCODE]])),ISNUMBER(SEARCH("_unpowered",CONTROL[[#This Row],[VEHIDCODE]]))),"Special", _xlpm.l="WAGONS","wagons\"&SUBSTITUTE(_xlfn.TEXTBEFORE(SUBSTITUTE(_xlfn.TEXTAFTER(CONTROL[[#This Row],[VEHIDCODE]],"_",2),"Service_Car","Service#Car"),"_"),"#","_"), _xlpm.l="WAGONS_MGLV","Wagons_Maglev\"&_xlfn.TEXTBEFORE(_xlfn.TEXTAFTER(CONTROL[[#This Row],[VEHIDCODE]],"_",2),"_"), _xlpm.l="COACHES","Coaches\"&_xlfn.TEXTBEFORE(_xlfn.TEXTAFTER(CONTROL[[#This Row],[VEHIDCODE]],"_",2),"_"), _xlpm.l="COACHES_MGLV","Coaches_Maglev\"&_xlfn.TEXTBEFORE(_xlfn.TEXTAFTER(CONTROL[[#This Row],[VEHIDCODE]],"_",2),"_") )))} -> src\Railbus\Railbus_Steam | D5: {="ID_RANGE_"&_xlfn.IFS( ISNUMBER(SEARCH("mglv_maglev_wagon",CONTROL[[#This Row],[VEHIDCODE]])),"UNIT_WAGONS_MGLV", ISNUMBER(SEARCH("mu_mu_cargo_wagon",CONTROL[[#This Row],[VEHIDCODE]])),"UNIT_WAGONS_RAIL_CARGO", ISNUMBER(SEARCH("mtro_metro_wagon_",CONTROL[[#This Row],[VEHIDCODE]])),"UNIT_WAGONS_MTRO", ISNUMBER(SEARCH("mu_mu_wagon",CONTROL[[#This Row],[VEHIDCODE]])),"UNIT_WAGONS_RAIL", ISNUMBER(SEARCH("mu_wagon",CONTROL[[#This Row],[VEHIDCODE]])),"WAGONS", ISNUMBER(SEARCH("mu_coach",CONTROL[[#This Row],[VEHIDCODE]])),"COACHES", ISNUMBER(SEARCH("mglv_coach",CONTROL[[#This Row],[VEHIDCODE]])),"COACHES_MGLV", _xlfn.TEXTBEFORE(CONTROL[[#This Row],[VEHIDCODE]],"_")="rbs","RBS", _xlfn.TEXTBEFORE(CONTROL[[#This Row],[VEHIDCODE]],"_")="rbd","RBD", _xlfn.TEXTBEFORE(CONTROL[[#This Row],[VEHIDCODE]],"_")="rbe","RBE", _xlfn.TEXTBEFORE(CONTROL[[#This Row],[VEHIDCODE]],"_")="rbm","RBM", _xlfn.TEXTBEFORE(CONTROL[[#This Row],[VEHIDCODE]],"_")="steam","STEAM", _xlfn.TEXTBEFORE(CONTROL[[#This Row],[VEHIDCODE]],"_")="diesel","DIESEL", _xlfn.TEXTBEFORE(CONTROL[[#This Row],[VEHIDCODE]],"_")="electric","ELECTRIC", _xlfn.TEXTBEFORE(CONTROL[[#This Row],[VEHIDCODE]],"_")="mtro","MULTIMETRO", _xlfn.TEXTBEFORE(CONTROL[[#This Row],[VEHIDCODE]],"_")="singlemtro","SINGLEMETRO", _xlfn.TEXTBEFORE(CONTROL[[#This Row],[VEHIDCODE]],"_")="dmu","DMU", _xlfn.TEXTBEFORE(CONTROL[[#This Row],[VEHIDCODE]],"_")="cargodmu","CARGODMU", _xlfn.TEXTBEFORE(CONTROL[[#This Row],[VEHIDCODE]],"_")="emu","EMU", _xlfn.TEXTBEFORE(CONTROL[[#This Row],[VEHIDCODE]],"_")="cargoemu","CARGOEMU", _xlfn.TEXTBEFORE(CONTROL[[#This Row],[VEHIDCODE]],"_",2)="mglv_Wagon","WAGONS_MGLV", AND(_xlfn.TEXTBEFORE(CONTROL[[#This Row],[VEHIDCODE]],"_",1)="mglv",_xlfn.XLOOKUP(CONTROL[[#This Row],[VEHIDCODE]],PROPERTIES[VEHIDCODE],PROPERTIES[DUAL_HEADED])=0),"MAGLEV", _xlfn.TEXTBEFORE(CONTROL[[#This Row],[VEHIDCODE]],"_")="mmu","MMU")} -> ID_RANGE_RBS | E5: 1001 | F5: Kerr, Stuart & Co. 86 | G5: https://it.wikipedia.org/wiki/Automotrice_FS_86 | H5: =AND(CONTROL[[#This Row],[IS_WAGON_OR_COACH]]=TRUE,OR(RIGHT(CONTROL[[#This Row],[VEHIDCODE]],7)="Powered",RIGHT(CONTROL[[#This Row],[VEHIDCODE]],9)="Unpowered")) -> FALSE | I5: =OR(ISNUMBER(SEARCH("_wagon_powered",CONTROL[[#This Row],[VEHIDCODE]])),ISNUMBER(SEARCH("_wagon_unpowered",CONTROL[[#This Row],[VEHIDCODE]])),ISNUMBER(SEARCH("mu_wagon_",CONTROL[[#This Row],[VEHIDCODE]])),ISNUMBER(SEARCH("mglv_wagon_",CONTROL[[#This Row],[VEHIDCODE]])),ISNUMBER(SEARCH("mu_coach_",CONTROL[[#This Row],[VEHIDCODE]])),ISNUMBER(SEARCH("mglv_coach_",CONTROL[[#This Row],[VEHIDCODE]]))) -> FALSE | J5: =ISNUMBER(_xlfn.XMATCH(CONTROL[[#This Row],[VEHIDCODE]],TRACK_TYPES[VEHIDCODE],0)) -> TRUE | K5: =ISNUMBER(_xlfn.XMATCH(CONTROL[[#This Row],[VEHIDCODE]],PROPERTIES[VEHIDCODE],0)) -> TRUE | L5: =ISNUMBER(_xlfn.XLOOKUP(CONTROL[[#This Row],[VEHIDCODE]],roster!A:A,roster!D:D)) -> TRUE | M5: =ISNUMBER(_xlfn.XMATCH(CONTROL[[#This Row],[VEHIDCODE]],GRAPHICS_PROPERTIES[VEHIDCODE],0)) -> TRUE | N5: ="item_"&CONTROL[[#This Row],[VEHIDCODE]] -> item_rbs_Kerr__Stuart___Co__86 | O5: ="str_"&CONTROL[[#This Row],[VEHIDCODE]] -> str_rbs_Kerr__Stuart___Co__86 | P5: =_xlfn.XLOOKUP(CONTROL[[#This Row],[VEHIDCODE]],PROPERTIES[VEHIDCODE],PROPERTIES[IS_CONCEPT])="IS_CONCEPT" -> FALSE | Q5: =_xlfn.XLOOKUP(CONTROL[[#This Row],[VEHIDCODE]],PROPERTIES[VEHIDCODE],PROPERTIES[EXCLUDE]) -> FALSE | R5: {=_xlfn.XLOOKUP(CONTROL[[#This Row],[VEHIDCODE]],GRAPHICS_PROPERTIES[VEHIDCODE],GRAPHICS_PROPERTIES[TEMPLATE_ID]&GRAPHICS_PROPERTIES[TEMPLATE_AMENDMENT_CODE])} -> TPL_03C
A6: rbs_Victorian_Railways_Rowan_Railmotor | B6: =_xlfn.TEXTAFTER(CONTROL[[#This Row],[VEHIDCODE]],"_") -> Victorian_Railways_Rowan_Railmotor | C6: {="src\"&(_xlfn.LET(_xlpm.l,SUBSTITUTE(CONTROL[[#This Row],[VEHID_ID_CATEGORY]],"ID_RANGE_",""),_xlfn.IFS( _xlpm.l="RBS","Railbus\Railbus_Steam", _xlpm.l="RBD","Railbus\Railbus_Diesel", _xlpm.l="RBE","Railbus\Railbus_Electric", _xlpm.l="RBM","Railbus\Railbus_Maglev", _xlpm.l="STEAM","Steam", _xlpm.l="DIESEL","Diesel", OR(_xlpm.l="ELECTRIC", _xlpm.l="MULTIMETRO"),"Electric", _xlpm.l="MAGLEV","Maglev", _xlpm.l="MULTIMAGLEV","MMU", _xlpm.l="CARGODMU","CargoDMU", _xlpm.l="DMU","DMU", _xlpm.l="CARGOEMU","CargoEMU", _xlpm.l="EMU","EMU", _xlpm.l="MMU","MMU", _xlpm.l="SINGLEMETRO","Single_Metro", OR(ISNUMBER(SEARCH("_powered",CONTROL[[#This Row],[VEHIDCODE]])),ISNUMBER(SEARCH("_unpowered",CONTROL[[#This Row],[VEHIDCODE]]))),"Special", _xlpm.l="WAGONS","wagons\"&SUBSTITUTE(_xlfn.TEXTBEFORE(SUBSTITUTE(_xlfn.TEXTAFTER(CONTROL[[#This Row],[VEHIDCODE]],"_",2),"Service_Car","Service#Car"),"_"),"#","_"), _xlpm.l="WAGONS_MGLV","Wagons_Maglev\"&_xlfn.TEXTBEFORE(_xlfn.TEXTAFTER(CONTROL[[#This Row],[VEHIDCODE]],"_",2),"_"), _xlpm.l="COACHES","Coaches\"&_xlfn.TEXTBEFORE(_xlfn.TEXTAFTER(CONTROL[[#This Row],[VEHIDCODE]],"_",2),"_"), _xlpm.l="COACHES_MGLV","Coaches_Maglev\"&_xlfn.TEXTBEFORE(_xlfn.TEXTAFTER(CONTROL[[#This Row],[VEHIDCODE]],"_",2),"_") )))} -> src\Railbus\Railbus_Steam | D6: {="ID_RANGE_"&_xlfn.IFS( ISNUMBER(SEARCH("mglv_maglev_wagon",CONTROL[[#This Row],[VEHIDCODE]])),"UNIT_WAGONS_MGLV", ISNUMBER(SEARCH("mu_mu_cargo_wagon",CONTROL[[#This Row],[VEHIDCODE]])),"UNIT_WAGONS_RAIL_CARGO", ISNUMBER(SEARCH("mtro_metro_wagon_",CONTROL[[#This Row],[VEHIDCODE]])),"UNIT_WAGONS_MTRO", ISNUMBER(SEARCH("mu_mu_wagon",CONTROL[[#This Row],[VEHIDCODE]])),"UNIT_WAGONS_RAIL", ISNUMBER(SEARCH("mu_wagon",CONTROL[[#This Row],[VEHIDCODE]])),"WAGONS", ISNUMBER(SEARCH("mu_coach",CONTROL[[#This Row],[VEHIDCODE]])),"COACHES", ISNUMBER(SEARCH("mglv_coach",CONTROL[[#This Row],[VEHIDCODE]])),"COACHES_MGLV", _xlfn.TEXTBEFORE(CONTROL[[#This Row],[VEHIDCODE]],"_")="rbs","RBS", _xlfn.TEXTBEFORE(CONTROL[[#This Row],[VEHIDCODE]],"_")="rbd","RBD", _xlfn.TEXTBEFORE(CONTROL[[#This Row],[VEHIDCODE]],"_")="rbe","RBE", _xlfn.TEXTBEFORE(CONTROL[[#This Row],[VEHIDCODE]],"_")="rbm","RBM", _xlfn.TEXTBEFORE(CONTROL[[#This Row],[VEHIDCODE]],"_")="steam","STEAM", _xlfn.TEXTBEFORE(CONTROL[[#This Row],[VEHIDCODE]],"_")="diesel","DIESEL", _xlfn.TEXTBEFORE(CONTROL[[#This Row],[VEHIDCODE]],"_")="electric","ELECTRIC", _xlfn.TEXTBEFORE(CONTROL[[#This Row],[VEHIDCODE]],"_")="mtro","MULTIMETRO", _xlfn.TEXTBEFORE(CONTROL[[#This Row],[VEHIDCODE]],"_")="singlemtro","SINGLEMETRO", _xlfn.TEXTBEFORE(CONTROL[[#This Row],[VEHIDCODE]],"_")="dmu","DMU", _xlfn.TEXTBEFORE(CONTROL[[#This Row],[VEHIDCODE]],"_")="cargodmu","CARGODMU", _xlfn.TEXTBEFORE(CONTROL[[#This Row],[VEHIDCODE]],"_")="emu","EMU", _xlfn.TEXTBEFORE(CONTROL[[#This Row],[VEHIDCODE]],"_")="cargoemu","CARGOEMU", _xlfn.TEXTBEFORE(CONTROL[[#This Row],[VEHIDCODE]],"_",2)="mglv_Wagon","WAGONS_MGLV", AND(_xlfn.TEXTBEFORE(CONTROL[[#This Row],[VEHIDCODE]],"_",1)="mglv",_xlfn.XLOOKUP(CONTROL[[#This Row],[VEHIDCODE]],PROPERTIES[VEHIDCODE],PROPERTIES[DUAL_HEADED])=0),"MAGLEV", _xlfn.TEXTBEFORE(CONTROL[[#This Row],[VEHIDCODE]],"_")="mmu","MMU")} -> ID_RANGE_RBS | E6: 1002 | F6: Victorian Railways Rowan Railmotor | G6: https://en.wikipedia.org/wiki/Rowan_steam_railmotor | H6: =AND(CONTROL[[#This Row],[IS_WAGON_OR_COACH]]=TRUE,OR(RIGHT(CONTROL[[#This Row],[VEHIDCODE]],7)="Powered",RIGHT(CONTROL[[#This Row],[VEHIDCODE]],9)="Unpowered")) -> FALSE | I6: =OR(ISNUMBER(SEARCH("_wagon_powered",CONTROL[[#This Row],[VEHIDCODE]])),ISNUMBER(SEARCH("_wagon_unpowered",CONTROL[[#This Row],[VEHIDCODE]])),ISNUMBER(SEARCH("mu_wagon_",CONTROL[[#This Row],[VEHIDCODE]])),ISNUMBER(SEARCH("mglv_wagon_",CONTROL[[#This Row],[VEHIDCODE]])),ISNUMBER(SEARCH("mu_coach_",CONTROL[[#This Row],[VEHIDCODE]])),ISNUMBER(SEARCH("mglv_coach_",CONTROL[[#This Row],[VEHIDCODE]]))) -> FALSE | J6: =ISNUMBER(_xlfn.XMATCH(CONTROL[[#This Row],[VEHIDCODE]],TRACK_TYPES[VEHIDCODE],0)) -> TRUE | K6: =ISNUMBER(_xlfn.XMATCH(CONTROL[[#This Row],[VEHIDCODE]],PROPERTIES[VEHIDCODE],0)) -> TRUE | L6: =ISNUMBER(_xlfn.XLOOKUP(CONTROL[[#This Row],[VEHIDCODE]],roster!A:A,roster!D:D)) -> TRUE | M6: =ISNUMBER(_xlfn.XMATCH(CONTROL[[#This Row],[VEHIDCODE]],GRAPHICS_PROPERTIES[VEHIDCODE],0)) -> TRUE | N6: ="item_"&CONTROL[[#This Row],[VEHIDCODE]] -> item_rbs_Victorian_Railways_Rowan_Railmotor | O6: ="str_"&CONTROL[[#This Row],[VEHIDCODE]] -> str_rbs_Victorian_Railways_Rowan_Railmotor | P6: =_xlfn.XLOOKUP(CONTROL[[#This Row],[VEHIDCODE]],PROPERTIES[VEHIDCODE],PROPERTIES[IS_CONCEPT])="IS_CONCEPT" -> FALSE | Q6: =_xlfn.XLOOKUP(CONTROL[[#This Row],[VEHIDCODE]],PROPERTIES[VEHIDCODE],PROPERTIES[EXCLUDE]) -> FALSE | R6: {=_xlfn.XLOOKUP(CONTROL[[#This Row],[VEHIDCODE]],GRAPHICS_PROPERTIES[VEHIDCODE],GRAPHICS_PROPERTIES[TEMPLATE_ID]&GRAPHICS_PROPERTIES[TEMPLATE_AMENDMENT_CODE])} -> TPL_03C
A7: rbs_Esslingen_Czm_1_2 | B7: =_xlfn.TEXTAFTER(CONTROL[[#This Row],[VEHIDCODE]],"_") -> Esslingen_Czm_1_2 | C7: {="src\"&(_xlfn.LET(_xlpm.l,SUBSTITUTE(CONTROL[[#This Row],[VEHID_ID_CATEGORY]],"ID_RANGE_",""),_xlfn.IFS( _xlpm.l="RBS","Railbus\Railbus_Steam", _xlpm.l="RBD","Railbus\Railbus_Diesel", _xlpm.l="RBE","Railbus\Railbus_Electric", _xlpm.l="RBM","Railbus\Railbus_Maglev", _xlpm.l="STEAM","Steam", _xlpm.l="DIESEL","Diesel", OR(_xlpm.l="ELECTRIC", _xlpm.l="MULTIMETRO"),"Electric", _xlpm.l="MAGLEV","Maglev", _xlpm.l="MULTIMAGLEV","MMU", _xlpm.l="CARGODMU","CargoDMU", _xlpm.l="DMU","DMU", _xlpm.l="CARGOEMU","CargoEMU", _xlpm.l="EMU","EMU", _xlpm.l="MMU","MMU", _xlpm.l="SINGLEMETRO","Single_Metro", OR(ISNUMBER(SEARCH("_powered",CONTROL[[#This Row],[VEHIDCODE]])),ISNUMBER(SEARCH("_unpowered",CONTROL[[#This Row],[VEHIDCODE]]))),"Special", _xlpm.l="WAGONS","wagons\"&SUBSTITUTE(_xlfn.TEXTBEFORE(SUBSTITUTE(_xlfn.TEXTAFTER(CONTROL[[#This Row],[VEHIDCODE]],"_",2),"Service_Car","Service#Car"),"_"),"#","_"), _xlpm.l="WAGONS_MGLV","Wagons_Maglev\"&_xlfn.TEXTBEFORE(_xlfn.TEXTAFTER(CONTROL[[#This Row],[VEHIDCODE]],"_",2),"_"), _xlpm.l="COACHES","Coaches\"&_xlfn.TEXTBEFORE(_xlfn.TEXTAFTER(CONTROL[[#This Row],[VEHIDCODE]],"_",2),"_"), _xlpm.l="COACHES_MGLV","Coaches_Maglev\"&_xlfn.TEXTBEFORE(_xlfn.TEXTAFTER(CONTROL[[#This Row],[VEHIDCODE]],"_",2),"_") )))} -> src\Railbus\Railbus_Steam | D7: {="ID_RANGE_"&_xlfn.IFS( ISNUMBER(SEARCH("mglv_maglev_wagon",CONTROL[[#This Row],[VEHIDCODE]])),"UNIT_WAGONS_MGLV", ISNUMBER(SEARCH("mu_mu_cargo_wagon",CONTROL[[#This Row],[VEHIDCODE]])),"UNIT_WAGONS_RAIL_CARGO", ISNUMBER(SEARCH("mtro_metro_wagon_",CONTROL[[#This Row],[VEHIDCODE]])),"UNIT_WAGONS_MTRO", ISNUMBER(SEARCH("mu_mu_wagon",CONTROL[[#This Row],[VEHIDCODE]])),"UNIT_WAGONS_RAIL", ISNUMBER(SEARCH("mu_wagon",CONTROL[[#This Row],[VEHIDCODE]])),"WAGONS", ISNUMBER(SEARCH("mu_coach",CONTROL[[#This Row],[VEHIDCODE]])),"COACHES", ISNUMBER(SEARCH("mglv_coach",CONTROL[[#This Row],[VEHIDCODE]])),"COACHES_MGLV", _xlfn.TEXTBEFORE(CONTROL[[#This Row],[VEHIDCODE]],"_")="rbs","RBS", _xlfn.TEXTBEFORE(CONTROL[[#This Row],[VEHIDCODE]],"_")="rbd","RBD", _xlfn.TEXTBEFORE(CONTROL[[#This Row],[VEHIDCODE]],"_")="rbe","RBE", _xlfn.TEXTBEFORE(CONTROL[[#This Row],[VEHIDCODE]],"_")="rbm","RBM", _xlfn.TEXTBEFORE(CONTROL[[#This Row],[VEHIDCODE]],"_")="steam","STEAM", _xlfn.TEXTBEFORE(CONTROL[[#This Row],[VEHIDCODE]],"_")="diesel","DIESEL", _xlfn.TEXTBEFORE(CONTROL[[#This Row],[VEHIDCODE]],"_")="electric","ELECTRIC", _xlfn.TEXTBEFORE(CONTROL[[#This Row],[VEHIDCODE]],"_")="mtro","MULTIMETRO", _xlfn.TEXTBEFORE(CONTROL[[#This Row],[VEHIDCODE]],"_")="singlemtro","SINGLEMETRO", _xlfn.TEXTBEFORE(CONTROL[[#This Row],[VEHIDCODE]],"_")="dmu","DMU", _xlfn.TEXTBEFORE(CONTROL[[#This Row],[VEHIDCODE]],"_")="cargodmu","CARGODMU", _xlfn.TEXTBEFORE(CONTROL[[#This Row],[VEHIDCODE]],"_")="emu","EMU", _xlfn.TEXTBEFORE(CONTROL[[#This Row],[VEHIDCODE]],"_")="cargoemu","CARGOEMU", _xlfn.TEXTBEFORE(CONTROL[[#This Row],[VEHIDCODE]],"_",2)="mglv_Wagon","WAGONS_MGLV", AND(_xlfn.TEXTBEFORE(CONTROL[[#This Row],[VEHIDCODE]],"_",1)="mglv",_xlfn.XLOOKUP(CONTROL[[#This Row],[VEHIDCODE]],PROPERTIES[VEHIDCODE],PROPERTIES[DUAL_HEADED])=0),"MAGLEV", _xlfn.TEXTBEFORE(CONTROL[[#This Row],[VEHIDCODE]],"_")="mmu","MMU")} -> ID_RANGE_RBS | E7: 1003 | F7: Esslingen Czm 1/2 | G7: https://de.wikipedia.org/wiki/UeBB_CZm_1/2 | H7: =AND(CONTROL[[#This Row],[IS_WAGON_OR_COACH]]=TRUE,OR(RIGHT(CONTROL[[#This Row],[VEHIDCODE]],7)="Powered",RIGHT(CONTROL[[#This Row],[VEHIDCODE]],9)="Unpowered")) -> FALSE | I7: =OR(ISNUMBER(SEARCH("_wagon_powered",CONTROL[[#This Row],[VEHIDCODE]])),ISNUMBER(SEARCH("_wagon_unpowered",CONTROL[[#This Row],[VEHIDCODE]])),ISNUMBER(SEARCH("mu_wagon_",CONTROL[[#This Row],[VEHIDCODE]])),ISNUMBER(SEARCH("mglv_wagon_",CONTROL[[#This Row],[VEHIDCODE]])),ISNUMBER(SEARCH("mu_coach_",CONTROL[[#This Row],[VEHIDCODE]])),ISNUMBER(SEARCH("mglv_coach_",CONTROL[[#This Row],[VEHIDCODE]]))) -> FALSE | J7: =ISNUMBER(_xlfn.XMATCH(CONTROL[[#This Row],[VEHIDCODE]],TRACK_TYPES[VEHIDCODE],0)) -> TRUE | K7: =ISNUMBER(_xlfn.XMATCH(CONTROL[[#This Row],[VEHIDCODE]],PROPERTIES[VEHIDCODE],0)) -> TRUE | L7: =ISNUMBER(_xlfn.XLOOKUP(CONTROL[[#This Row],[VEHIDCODE]],roster!A:A,roster!D:D)) -> TRUE | M7: =ISNUMBER(_xlfn.XMATCH(CONTROL[[#This Row],[VEHIDCODE]],GRAPHICS_PROPERTIES[VEHIDCODE],0)) -> TRUE | N7: ="item_"&CONTROL[[#This Row],[VEHIDCODE]] -> item_rbs_Esslingen_Czm_1_2 | O7: ="str_"&CONTROL[[#This Row],[VEHIDCODE]] -> str_rbs_Esslingen_Czm_1_2 | P7: =_xlfn.XLOOKUP(CONTROL[[#This Row],[VEHIDCODE]],PROPERTIES[VEHIDCODE],PROPERTIES[IS_CONCEPT])="IS_CONCEPT" -> FALSE | Q7: =_xlfn.XLOOKUP(CONTROL[[#This Row],[VEHIDCODE]],PROPERTIES[VEHIDCODE],PROPERTIES[EXCLUDE]) -> FALSE | R7: {=_xlfn.XLOOKUP(CONTROL[[#This Row],[VEHIDCODE]],GRAPHICS_PROPERTIES[VEHIDCODE],GRAPHICS_PROPERTIES[TEMPLATE_ID]&GRAPHICS_PROPERTIES[TEMPLATE_AMENDMENT_CODE])} -> TPL_03C
A8: rbs_Maffei_MCCi | B8: =_xlfn.TEXTAFTER(CONTROL[[#This Row],[VEHIDCODE]],"_") -> Maffei_MCCi | C8: {="src\"&(_xlfn.LET(_xlpm.l,SUBSTITUTE(CONTROL[[#This Row],[VEHID_ID_CATEGORY]],"ID_RANGE_",""),_xlfn.IFS( _xlpm.l="RBS","Railbus\Railbus_Steam", _xlpm.l="RBD","Railbus\Railbus_Diesel", _xlpm.l="RBE","Railbus\Railbus_Electric", _xlpm.l="RBM","Railbus\Railbus_Maglev", _xlpm.l="STEAM","Steam", _xlpm.l="DIESEL","Diesel", OR(_xlpm.l="ELECTRIC", _xlpm.l="MULTIMETRO"),"Electric", _xlpm.l="MAGLEV","Maglev", _xlpm.l="MULTIMAGLEV","MMU", _xlpm.l="CARGODMU","CargoDMU", _xlpm.l="DMU","DMU", _xlpm.l="CARGOEMU","CargoEMU", _xlpm.l="EMU","EMU", _xlpm.l="MMU","MMU", _xlpm.l="SINGLEMETRO","Single_Metro", OR(ISNUMBER(SEARCH("_powered",CONTROL[[#This Row],[VEHIDCODE]])),ISNUMBER(SEARCH("_unpowered",CONTROL[[#This Row],[VEHIDCODE]]))),"Special", _xlpm.l="WAGONS","wagons\"&SUBSTITUTE(_xlfn.TEXTBEFORE(SUBSTITUTE(_xlfn.TEXTAFTER(CONTROL[[#This Row],[VEHIDCODE]],"_",2),"Service_Car","Service#Car"),"_"),"#","_"), _xlpm.l="WAGONS_MGLV","Wagons_Maglev\"&_xlfn.TEXTBEFORE(_xlfn.TEXTAFTER(CONTROL[[#This Row],[VEHIDCODE]],"_",2),"_"), _xlpm.l="COACHES","Coaches\"&_xlfn.TEXTBEFORE(_xlfn.TEXTAFTER(CONTROL[[#This Row],[VEHIDCODE]],"_",2),"_"), _xlpm.l="COACHES_MGLV","Coaches_Maglev\"&_xlfn.TEXTBEFORE(_xlfn.TEXTAFTER(CONTROL[[#This Row],[VEHIDCODE]],"_",2),"_") )))} -> src\Railbus\Railbus_Steam | D8: {="ID_RANGE_"&_xlfn.IFS( ISNUMBER(SEARCH("mglv_maglev_wagon",CONTROL[[#This Row],[VEHIDCODE]])),"UNIT_WAGONS_MGLV", ISNUMBER(SEARCH("mu_mu_cargo_wagon",CONTROL[[#This Row],[VEHIDCODE]])),"UNIT_WAGONS_RAIL_CARGO", ISNUMBER(SEARCH("mtro_metro_wagon_",CONTROL[[#This Row],[VEHIDCODE]])),"UNIT_WAGONS_MTRO", ISNUMBER(SEARCH("mu_mu_wagon",CONTROL[[#This Row],[VEHIDCODE]])),"UNIT_WAGONS_RAIL", ISNUMBER(SEARCH("mu_wagon",CONTROL[[#This Row],[VEHIDCODE]])),"WAGONS", ISNUMBER(SEARCH("mu_coach",CONTROL[[#This Row],[VEHIDCODE]])),"COACHES", ISNUMBER(SEARCH("mglv_coach",CONTROL[[#This Row],[VEHIDCODE]])),"COACHES_MGLV", _xlfn.TEXTBEFORE(CONTROL[[#This Row],[VEHIDCODE]],"_")="rbs","RBS", _xlfn.TEXTBEFORE(CONTROL[[#This Row],[VEHIDCODE]],"_")="rbd","RBD", _xlfn.TEXTBEFORE(CONTROL[[#This Row],[VEHIDCODE]],"_")="rbe","RBE", _xlfn.TEXTBEFORE(CONTROL[[#This Row],[VEHIDCODE]],"_")="rbm","RBM", _xlfn.TEXTBEFORE(CONTROL[[#This Row],[VEHIDCODE]],"_")="steam","STEAM", _xlfn.TEXTBEFORE(CONTROL[[#This Row],[VEHIDCODE]],"_")="diesel","DIESEL", _xlfn.TEXTBEFORE(CONTROL[[#This Row],[VEHIDCODE]],"_")="electric","ELECTRIC", _xlfn.TEXTBEFORE(CONTROL[[#This Row],[VEHIDCODE]],"_")="mtro","MULTIMETRO", _xlfn.TEXTBEFORE(CONTROL[[#This Row],[VEHIDCODE]],"_")="singlemtro","SINGLEMETRO", _xlfn.TEXTBEFORE(CONTROL[[#This Row],[VEHIDCODE]],"_")="dmu","DMU", _xlfn.TEXTBEFORE(CONTROL[[#This Row],[VEHIDCODE]],"_")="cargodmu","CARGODMU", _xlfn.TEXTBEFORE(CONTROL[[#This Row],[VEHIDCODE]],"_")="emu","EMU", _xlfn.TEXTBEFORE(CONTROL[[#This Row],[VEHIDCODE]],"_")="cargoemu","CARGOEMU", _xlfn.TEXTBEFORE(CONTROL[[#This Row],[VEHIDCODE]],"_",2)="mglv_Wagon","WAGONS_MGLV", AND(_xlfn.TEXTBEFORE(CONTROL[[#This Row],[VEHIDCODE]],"_",1)="mglv",_xlfn.XLOOKUP(CONTROL[[#This Row],[VEHIDCODE]],PROPERTIES[VEHIDCODE],PROPERTIES[DUAL_HEADED])=0),"MAGLEV", _xlfn.TEXTBEFORE(CONTROL[[#This Row],[VEHIDCODE]],"_")="mmu","MMU")} -> ID_RANGE_RBS | E8: 1004 | F8: Maffei MCCi | G8: https://en.wikipedia.org/wiki/Bavarian_MCCi | H8: =AND(CONTROL[[#This Row],[IS_WAGON_OR_COACH]]=TRUE,OR(RIGHT(CONTROL[[#This Row],[VEHIDCODE]],7)="Powered",RIGHT(CONTROL[[#This Row],[VEHIDCODE]],9)="Unpowered")) -> FALSE | I8: =OR(ISNUMBER(SEARCH("_wagon_powered",CONTROL[[#This Row],[VEHIDCODE]])),ISNUMBER(SEARCH("_wagon_unpowered",CONTROL[[#This Row],[VEHIDCODE]])),ISNUMBER(SEARCH("mu_wagon_",CONTROL[[#This Row],[VEHIDCODE]])),ISNUMBER(SEARCH("mglv_wagon_",CONTROL[[#This Row],[VEHIDCODE]])),ISNUMBER(SEARCH("mu_coach_",CONTROL[[#This Row],[VEHIDCODE]])),ISNUMBER(SEARCH("mglv_coach_",CONTROL[[#This Row],[VEHIDCODE]]))) -> FALSE | J8: =ISNUMBER(_xlfn.XMATCH(CONTROL[[#This Row],[VEHIDCODE]],TRACK_TYPES[VEHIDCODE],0)) -> TRUE | K8: =ISNUMBER(_xlfn.XMATCH(CONTROL[[#This Row],[VEHIDCODE]],PROPERTIES[VEHIDCODE],0)) -> TRUE | L8: =ISNUMBER(_xlfn.XLOOKUP(CONTROL[[#This Row],[VEHIDCODE]],roster!A:A,roster!D:D)) -> TRUE | M8: =ISNUMBER(_xlfn.XMATCH(CONTROL[[#This Row],[VEHIDCODE]],GRAPHICS_PROPERTIES[VEHIDCODE],0)) -> TRUE | N8: ="item_"&CONTROL[[#This Row],[VEHIDCODE]] -> item_rbs_Maffei_MCCi | O8: ="str_"&CONTROL[[#This Row],[VEHIDCODE]] -> str_rbs_Maffei_MCCi | P8: =_xlfn.XLOOKUP(CONTROL[[#This Row],[VEHIDCODE]],PROPERTIES[VEHIDCODE],PROPERTIES[IS_CONCEPT])="IS_CONCEPT" -> FALSE | Q8: =_xlfn.XLOOKUP(CONTROL[[#This Row],[VEHIDCODE]],PROPERTIES[VEHIDCODE],PROPERTIES[EXCLUDE]) -> FALSE | R8: {=_xlfn.XLOOKUP(CONTROL[[#This Row],[VEHIDCODE]],GRAPHICS_PROPERTIES[VEHIDCODE],GRAPHICS_PROPERTIES[TEMPLATE_ID]&GRAPHICS_PROPERTIES[TEMPLATE_AMENDMENT_CODE])} -> TPL_01B
A9: rbs_Kitson___Co_CSAR_Railmotor | B9: =_xlfn.TEXTAFTER(CONTROL[[#This Row],[VEHIDCODE]],"_") -> Kitson___Co_CSAR_Railmotor | C9: {="src\"&(_xlfn.LET(_xlpm.l,SUBSTITUTE(CONTROL[[#This Row],[VEHID_ID_CATEGORY]],"ID_RANGE_",""),_xlfn.IFS( _xlpm.l="RBS","Railbus\Railbus_Steam", _xlpm.l="RBD","Railbus\Railbus_Diesel", _xlpm.l="RBE","Railbus\Railbus_Electric", _xlpm.l="RBM","Railbus\Railbus_Maglev", _xlpm.l="STEAM","Steam", _xlpm.l="DIESEL","Diesel", OR(_xlpm.l="ELECTRIC", _xlpm.l="MULTIMETRO"),"Electric", _xlpm.l="MAGLEV","Maglev", _xlpm.l="MULTIMAGLEV","MMU", _xlpm.l="CARGODMU","CargoDMU", _xlpm.l="DMU","DMU", _xlpm.l="CARGOEMU","CargoEMU", _xlpm.l="EMU","EMU", _xlpm.l="MMU","MMU", _xlpm.l="SINGLEMETRO","Single_Metro", OR(ISNUMBER(SEARCH("_powered",CONTROL[[#This Row],[VEHIDCODE]])),ISNUMBER(SEARCH("_unpowered",CONTROL[[#This Row],[VEHIDCODE]]))),"Special", _xlpm.l="WAGONS","wagons\"&SUBSTITUTE(_xlfn.TEXTBEFORE(SUBSTITUTE(_xlfn.TEXTAFTER(CONTROL[[#This Row],[VEHIDCODE]],"_",2),"Service_Car","Service#Car"),"_"),"#","_"), _xlpm.l="WAGONS_MGLV","Wagons_Maglev\"&_xlfn.TEXTBEFORE(_xlfn.TEXTAFTER(CONTROL[[#This Row],[VEHIDCODE]],"_",2),"_"), _xlpm.l="COACHES","Coaches\"&_xlfn.TEXTBEFORE(_xlfn.TEXTAFTER(CONTROL[[#This Row],[VEHIDCODE]],"_",2),"_"), _xlpm.l="COACHES_MGLV","Coaches_Maglev\"&_xlfn.TEXTBEFORE(_xlfn.TEXTAFTER(CONTROL[[#This Row],[VEHIDCODE]],"_",2),"_") )))} -> src\Railbus\Railbus_Steam | D9: {="ID_RANGE_"&_xlfn.IFS( ISNUMBER(SEARCH("mglv_maglev_wagon",CONTROL[[#This Row],[VEHIDCODE]])),"UNIT_WAGONS_MGLV", ISNUMBER(SEARCH("mu_mu_cargo_wagon",CONTROL[[#This Row],[VEHIDCODE]])),"UNIT_WAGONS_RAIL_CARGO", ISNUMBER(SEARCH("mtro_metro_wagon_",CONTROL[[#This Row],[VEHIDCODE]])),"UNIT_WAGONS_MTRO", ISNUMBER(SEARCH("mu_mu_wagon",CONTROL[[#This Row],[VEHIDCODE]])),"UNIT_WAGONS_RAIL", ISNUMBER(SEARCH("mu_wagon",CONTROL[[#This Row],[VEHIDCODE]])),"WAGONS", ISNUMBER(SEARCH("mu_coach",CONTROL[[#This Row],[VEHIDCODE]])),"COACHES", ISNUMBER(SEARCH("mglv_coach",CONTROL[[#This Row],[VEHIDCODE]])),"COACHES_MGLV", _xlfn.TEXTBEFORE(CONTROL[[#This Row],[VEHIDCODE]],"_")="rbs","RBS", _xlfn.TEXTBEFORE(CONTROL[[#This Row],[VEHIDCODE]],"_")="rbd","RBD", _xlfn.TEXTBEFORE(CONTROL[[#This Row],[VEHIDCODE]],"_")="rbe","RBE", _xlfn.TEXTBEFORE(CONTROL[[#This Row],[VEHIDCODE]],"_")="rbm","RBM", _xlfn.TEXTBEFORE(CONTROL[[#This Row],[VEHIDCODE]],"_")="steam","STEAM", _xlfn.TEXTBEFORE(CONTROL[[#This Row],[VEHIDCODE]],"_")="diesel","DIESEL", _xlfn.TEXTBEFORE(CONTROL[[#This Row],[VEHIDCODE]],"_")="electric","ELECTRIC", _xlfn.TEXTBEFORE(CONTROL[[#This Row],[VEHIDCODE]],"_")="mtro","MULTIMETRO", _xlfn.TEXTBEFORE(CONTROL[[#This Row],[VEHIDCODE]],"_")="singlemtro","SINGLEMETRO", _xlfn.TEXTBEFORE(CONTROL[[#This Row],[VEHIDCODE]],"_")="dmu","DMU", _xlfn.TEXTBEFORE(CONTROL[[#This Row],[VEHIDCODE]],"_")="cargodmu","CARGODMU", _xlfn.TEXTBEFORE(CONTROL[[#This Row],[VEHIDCODE]],"_")="emu","EMU", _xlfn.TEXTBEFORE(CONTROL[[#This Row],[VEHIDCODE]],"_")="cargoemu","CARGOEMU", _xlfn.TEXTBEFORE(CONTROL[[#This Row],[VEHIDCODE]],"_",2)="mglv_Wagon","WAGONS_MGLV", AND(_xlfn.TEXTBEFORE(CONTROL[[#This Row],[VEHIDCODE]],"_",1)="mglv",_xlfn.XLOOKUP(CONTROL[[#This Row],[VEHIDCODE]],PROPERTIES[VEHIDCODE],PROPERTIES[DUAL_HEADED])=0),"MAGLEV", _xlfn.TEXTBEFORE(CONTROL[[#This Row],[VEHIDCODE]],"_")="mmu","MMU")} -> ID_RANGE_RBS | E9: 1005 | F9: Kitson & Co. CSAR Railmotor | G9: https://en.wikipedia.org/wiki/CSAR_Railmotor | H9: =AND(CONTROL[[#This Row],[IS_WAGON_OR_COACH]]=TRUE,OR(RIGHT(CONTROL[[#This Row],[VEHIDCODE]],7)="Powered",RIGHT(CONTROL[[#This Row],[VEHIDCODE]],9)="Unpowered")) -> FALSE | I9: =OR(ISNUMBER(SEARCH("_wagon_powered",CONTROL[[#This Row],[VEHIDCODE]])),ISNUMBER(SEARCH("_wagon_unpowered",CONTROL[[#This Row],[VEHIDCODE]])),ISNUMBER(SEARCH("mu_wagon_",CONTROL[[#This Row],[VEHIDCODE]])),ISNUMBER(SEARCH("mglv_wagon_",CONTROL[[#This Row],[VEHIDCODE]])),ISNUMBER(SEARCH("mu_coach_",CONTROL[[#This Row],[VEHIDCODE]])),ISNUMBER(SEARCH("mglv_coach_",CONTROL[[#This Row],[VEHIDCODE]]))) -> FALSE | J9: =ISNUMBER(_xlfn.XMATCH(CONTROL[[#This Row],[VEHIDCODE]],TRACK_TYPES[VEHIDCODE],0)) -> TRUE | K9: =ISNUMBER(_xlfn.XMATCH(CONTROL[[#This Row],[VEHIDCODE]],PROPERTIES[VEHIDCODE],0)) -> TRUE | L9: =ISNUMBER(_xlfn.XLOOKUP(CONTROL[[#This Row],[VEHIDCODE]],roster!A:A,roster!D:D)) -> TRUE | M9: =ISNUMBER(_xlfn.XMATCH(CONTROL[[#This Row],[VEHIDCODE]],GRAPHICS_PROPERTIES[VEHIDCODE],0)) -> TRUE | N9: ="item_"&CONTROL[[#This Row],[VEHIDCODE]] -> item_rbs_Kitson___Co_CSAR_Railmotor | O9: ="str_"&CONTROL[[#This Row],[VEHIDCODE]] -> str_rbs_Kitson___Co_CSAR_Railmotor | P9: =_xlfn.XLOOKUP(CONTROL[[#This Row],[VEHIDCODE]],PROPERTIES[VEHIDCODE],PROPERTIES[IS_CONCEPT])="IS_CONCEPT" -> FALSE | Q9: =_xlfn.XLOOKUP(CONTROL[[#This Row],[VEHIDCODE]],PROPERTIES[VEHIDCODE],PROPERTIES[EXCLUDE]) -> FALSE | R9: {=_xlfn.XLOOKUP(CONTROL[[#This Row],[VEHIDCODE]],GRAPHICS_PROPERTIES[VEHIDCODE],GRAPHICS_PROPERTIES[TEMPLATE_ID]&GRAPHICS_PROPERTIES[TEMPLATE_AMENDMENT_CODE])} -> TPL_32B
A10: rbs_Kerr_Stuart_steam_railmotor | B10: =_xlfn.TEXTAFTER(CONTROL[[#This Row],[VEHIDCODE]],"_") -> Kerr_Stuart_steam_railmotor | C10: {="src\"&(_xlfn.LET(_xlpm.l,SUBSTITUTE(CONTROL[[#This Row],[VEHID_ID_CATEGORY]],"ID_RANGE_",""),_xlfn.IFS( _xlpm.l="RBS","Railbus\Railbus_Steam", _xlpm.l="RBD","Railbus\Railbus_Diesel", _xlpm.l="RBE","Railbus\Railbus_Electric", _xlpm.l="RBM","Railbus\Railbus_Maglev", _xlpm.l="STEAM","Steam", _xlpm.l="DIESEL","Diesel", OR(_xlpm.l="ELECTRIC", _xlpm.l="MULTIMETRO"),"Electric", _xlpm.l="MAGLEV","Maglev", _xlpm.l="MULTIMAGLEV","MMU", _xlpm.l="CARGODMU","CargoDMU", _xlpm.l="DMU","DMU", _xlpm.l="CARGOEMU","CargoEMU", _xlpm.l="EMU","EMU", _xlpm.l="MMU","MMU", _xlpm.l="SINGLEMETRO","Single_Metro", OR(ISNUMBER(SEARCH("_powered",CONTROL[[#This Row],[VEHIDCODE]])),ISNUMBER(SEARCH("_unpowered",CONTROL[[#This Row],[VEHIDCODE]]))),"Special", _xlpm.l="WAGONS","wagons\"&SUBSTITUTE(_xlfn.TEXTBEFORE(SUBSTITUTE(_xlfn.TEXTAFTER(CONTROL[[#This Row],[VEHIDCODE]],"_",2),"Service_Car","Service#Car"),"_"),"#","_"), _xlpm.l="WAGONS_MGLV","Wagons_Maglev\"&_xlfn.TEXTBEFORE(_xlfn.TEXTAFTER(CONTROL[[#This Row],[VEHIDCODE]],"_",2),"_"), _xlpm.l="COACHES","Coaches\"&_xlfn.TEXTBEFORE(_xlfn.TEXTAFTER(CONTROL[[#This Row],[VEHIDCODE]],"_",2),"_"), _xlpm.l="COACHES_MGLV","Coaches_Maglev\"&_xlfn.TEXTBEFORE(_xlfn.TEXTAFTER(CONTROL[[#This Row],[VEHIDCODE]],"_",2),"_") )))} -> src\Railbus\Railbus_Steam | D10: {="ID_RANGE_"&_xlfn.IFS( ISNUMBER(SEARCH("mglv_maglev_wagon",CONTROL[[#This Row],[VEHIDCODE]])),"UNIT_WAGONS_MGLV", ISNUMBER(SEARCH("mu_mu_cargo_wagon",CONTROL[[#This Row],[VEHIDCODE]])),"UNIT_WAGONS_RAIL_CARGO", ISNUMBER(SEARCH("mtro_metro_wagon_",CONTROL[[#This Row],[VEHIDCODE]])),"UNIT_WAGONS_MTRO", ISNUMBER(SEARCH("mu_mu_wagon",CONTROL[[#This Row],[VEHIDCODE]])),"UNIT_WAGONS_RAIL", ISNUMBER(SEARCH("mu_wagon",CONTROL[[#This Row],[VEHIDCODE]])),"WAGONS", ISNUMBER(SEARCH("mu_coach",CONTROL[[#This Row],[VEHIDCODE]])),"COACHES", ISNUMBER(SEARCH("mglv_coach",CONTROL[[#This Row],[VEHIDCODE]])),"COACHES_MGLV", _xlfn.TEXTBEFORE(CONTROL[[#This Row],[VEHIDCODE]],"_")="rbs","RBS", _xlfn.TEXTBEFORE(CONTROL[[#This Row],[VEHIDCODE]],"_")="rbd","RBD", _xlfn.TEXTBEFORE(CONTROL[[#This Row],[VEHIDCODE]],"_")="rbe","RBE", _xlfn.TEXTBEFORE(CONTROL[[#This Row],[VEHIDCODE]],"_")="rbm","RBM", _xlfn.TEXTBEFORE(CONTROL[[#This Row],[VEHIDCODE]],"_")="steam","STEAM", _xlfn.TEXTBEFORE(CONTROL[[#This Row],[VEHIDCODE]],"_")="diesel","DIESEL", _xlfn.TEXTBEFORE(CONTROL[[#This Row],[VEHIDCODE]],"_")="electric","ELECTRIC", _xlfn.TEXTBEFORE(CONTROL[[#This Row],[VEHIDCODE]],"_")="mtro","MULTIMETRO", _xlfn.TEXTBEFORE(CONTROL[[#This Row],[VEHIDCODE]],"_")="singlemtro","SINGLEMETRO", _xlfn.TEXTBEFORE(CONTROL[[#This Row],[VEHIDCODE]],"_")="dmu","DMU", _xlfn.TEXTBEFORE(CONTROL[[#This Row],[VEHIDCODE]],"_")="cargodmu","CARGODMU", _xlfn.TEXTBEFORE(CONTROL[[#This Row],[VEHIDCODE]],"_")="emu","EMU", _xlfn.TEXTBEFORE(CONTROL[[#This Row],[VEHIDCODE]],"_")="cargoemu","CARGOEMU", _xlfn.TEXTBEFORE(CONTROL[[#This Row],[VEHIDCODE]],"_",2)="mglv_Wagon","WAGONS_MGLV", AND(_xlfn.TEXTBEFORE(CONTROL[[#This Row],[VEHIDCODE]],"_",1)="mglv",_xlfn.XLOOKUP(CONTROL[[#This Row],[VEHIDCODE]],PROPERTIES[VEHIDCODE],PROPERTIES[DUAL_HEADED])=0),"MAGLEV", _xlfn.TEXTBEFORE(CONTROL[[#This Row],[VEHIDCODE]],"_")="mmu","MMU")} -> ID_RANGE_RBS | E10: 1006 | F10: Kerr, Stuart & Co. Motor Car 3 | G10: https://en.wikipedia.org/wiki/Kerr_Stuart_steam_railmotor | H10: =AND(CONTROL[[#This Row],[IS_WAGON_OR_COACH]]=TRUE,OR(RIGHT(CONTROL[[#This Row],[VEHIDCODE]],7)="Powered",RIGHT(CONTROL[[#This Row],[VEHIDCODE]],9)="Unpowered")) -> FALSE | I10: =OR(ISNUMBER(SEARCH("_wagon_powered",CONTROL[[#This Row],[VEHIDCODE]])),ISNUMBER(SEARCH("_wagon_unpowered",CONTROL[[#This Row],[VEHIDCODE]])),ISNUMBER(SEARCH("mu_wagon_",CONTROL[[#This Row],[VEHIDCODE]])),ISNUMBER(SEARCH("mglv_wagon_",CONTROL[[#This Row],[VEHIDCODE]])),ISNUMBER(SEARCH("mu_coach_",CONTROL[[#This Row],[VEHIDCODE]])),ISNUMBER(SEARCH("mglv_coach_",CONTROL[[#This Row],[VEHIDCODE]]))) -> FALSE | J10: =ISNUMBER(_xlfn.XMATCH(CONTROL[[#This Row],[VEHIDCODE]],TRACK_TYPES[VEHIDCODE],0)) -> TRUE | K10: =ISNUMBER(_xlfn.XMATCH(CONTROL[[#This Row],[VEHIDCODE]],PROPERTIES[VEHIDCODE],0)) -> TRUE | L10: =ISNUMBER(_xlfn.XLOOKUP(CONTROL[[#This Row],[VEHIDCODE]],roster!A:A,roster!D:D)) -> TRUE | M10: =ISNUMBER(_xlfn.XMATCH(CONTROL[[#This Row],[VEHIDCODE]],GRAPHICS_PROPERTIES[VEHIDCODE],0)) -> TRUE | N10: ="item_"&CONTROL[[#This Row],[VEHIDCODE]] -> item_rbs_Kerr_Stuart_steam_railmotor | O10: ="str_"&CONTROL[[#This Row],[VEHIDCODE]] -> str_rbs_Kerr_Stuart_steam_railmotor | P10: =_xlfn.XLOOKUP(CONTROL[[#This Row],[VEHIDCODE]],PROPERTIES[VEHIDCODE],PROPERTIES[IS_CONCEPT])="IS_CONCEPT" -> FALSE | Q10: =_xlfn.XLOOKUP(CONTROL[[#This Row],[VEHIDCODE]],PROPERTIES[VEHIDCODE],PROPERTIES[EXCLUDE]) -> FALSE | R10: {=_xlfn.XLOOKUP(CONTROL[[#This Row],[VEHIDCODE]],GRAPHICS_PROPERTIES[VEHIDCODE],GRAPHICS_PROPERTIES[TEMPLATE_ID]&GRAPHICS_PROPERTIES[TEMPLATE_AMENDMENT_CODE])} -> TPL_03C
A11: rbs_KkStB_4_0 | B11: =_xlfn.TEXTAFTER(CONTROL[[#This Row],[VEHIDCODE]],"_") -> KkStB_4_0 | C11: {="src\"&(_xlfn.LET(_xlpm.l,SUBSTITUTE(CONTROL[[#This Row],[VEHID_ID_CATEGORY]],"ID_RANGE_",""),_xlfn.IFS( _xlpm.l="RBS","Railbus\Railbus_Steam", _xlpm.l="RBD","Railbus\Railbus_Diesel", _xlpm.l="RBE","Railbus\Railbus_Electric", _xlpm.l="RBM","Railbus\Railbus_Maglev", _xlpm.l="STEAM","Steam", _xlpm.l="DIESEL","Diesel", OR(_xlpm.l="ELECTRIC", _xlpm.l="MULTIMETRO"),"Electric", _xlpm.l="MAGLEV","Maglev", _xlpm.l="MULTIMAGLEV","MMU", _xlpm.l="CARGODMU","CargoDMU", _xlpm.l="DMU","DMU", _xlpm.l="CARGOEMU","CargoEMU", _xlpm.l="EMU","EMU", _xlpm.l="MMU","MMU", _xlpm.l="SINGLEMETRO","Single_Metro", OR(ISNUMBER(SEARCH("_powered",CONTROL[[#This Row],[VEHIDCODE]])),ISNUMBER(SEARCH("_unpowered",CONTROL[[#This Row],[VEHIDCODE]]))),"Special", _xlpm.l="WAGONS","wagons\"&SUBSTITUTE(_xlfn.TEXTBEFORE(SUBSTITUTE(_xlfn.TEXTAFTER(CONTROL[[#This Row],[VEHIDCODE]],"_",2),"Service_Car","Service#Car"),"_"),"#","_"), _xlpm.l="WAGONS_MGLV","Wagons_Maglev\"&_xlfn.TEXTBEFORE(_xlfn.TEXTAFTER(CONTROL[[#This Row],[VEHIDCODE]],"_",2),"_"), _xlpm.l="COACHES","Coaches\"&_xlfn.TEXTBEFORE(_xlfn.TEXTAFTER(CONTROL[[#This Row],[VEHIDCODE]],"_",2),"_"), _xlpm.l="COACHES_MGLV","Coaches_Maglev\"&_xlfn.TEXTBEFORE(_xlfn.TEXTAFTER(CONTROL[[#This Row],[VEHIDCODE]],"_",2),"_") )))} -> src\Railbus\Railbus_Steam | D11: {="ID_RANGE_"&_xlfn.IFS( ISNUMBER(SEARCH("mglv_maglev_wagon",CONTROL[[#This Row],[VEHIDCODE]])),"UNIT_WAGONS_MGLV", ISNUMBER(SEARCH("mu_mu_cargo_wagon",CONTROL[[#This Row],[VEHIDCODE]])),"UNIT_WAGONS_RAIL_CARGO", ISNUMBER(SEARCH("mtro_metro_wagon_",CONTROL[[#This Row],[VEHIDCODE]])),"UNIT_WAGONS_MTRO", ISNUMBER(SEARCH("mu_mu_wagon",CONTROL[[#This Row],[VEHIDCODE]])),"UNIT_WAGONS_RAIL", ISNUMBER(SEARCH("mu_wagon",CONTROL[[#This Row],[VEHIDCODE]])),"WAGONS", ISNUMBER(SEARCH("mu_coach",CONTROL[[#This Row],[VEHIDCODE]])),"COACHES", ISNUMBER(SEARCH("mglv_coach",CONTROL[[#This Row],[VEHIDCODE]])),"COACHES_MGLV", _xlfn.TEXTBEFORE(CONTROL[[#This Row],[VEHIDCODE]],"_")="rbs","RBS", _xlfn.TEXTBEFORE(CONTROL[[#This Row],[VEHIDCODE]],"_")="rbd","RBD", _xlfn.TEXTBEFORE(CONTROL[[#This Row],[VEHIDCODE]],"_")="rbe","RBE", _xlfn.TEXTBEFORE(CONTROL[[#This Row],[VEHIDCODE]],"_")="rbm","RBM", _xlfn.TEXTBEFORE(CONTROL[[#This Row],[VEHIDCODE]],"_")="steam","STEAM", _xlfn.TEXTBEFORE(CONTROL[[#This Row],[VEHIDCODE]],"_")="diesel","DIESEL", _xlfn.TEXTBEFORE(CONTROL[[#This Row],[VEHIDCODE]],"_")="electric","ELECTRIC", _xlfn.TEXTBEFORE(CONTROL[[#This Row],[VEHIDCODE]],"_")="mtro","MULTIMETRO", _xlfn.TEXTBEFORE(CONTROL[[#This Row],[VEHIDCODE]],"_")="singlemtro","SINGLEMETRO", _xlfn.TEXTBEFORE(CONTROL[[#This Row],[VEHIDCODE]],"_")="dmu","DMU", _xlfn.TEXTBEFORE(CONTROL[[#This Row],[VEHIDCODE]],"_")="cargodmu","CARGODMU", _xlfn.TEXTBEFORE(CONTROL[[#This Row],[VEHIDCODE]],"_")="emu","EMU", _xlfn.TEXTBEFORE(CONTROL[[#This Row],[VEHIDCODE]],"_")="cargoemu","CARGOEMU", _xlfn.TEXTBEFORE(CONTROL[[#This Row],[VEHIDCODE]],"_",2)="mglv_Wagon","WAGONS_MGLV", AND(_xlfn.TEXTBEFORE(CONTROL[[#This Row],[VEHIDCODE]],"_",1)="mglv",_xlfn.XLOOKUP(CONTROL[[#This Row],[VEHIDCODE]],PROPERTIES[VEHIDCODE],PROPERTIES[DUAL_HEADED])=0),"MAGLEV", _xlfn.TEXTBEFORE(CONTROL[[#This Row],[VEHIDCODE]],"_")="mmu","MMU")} -> ID_RANGE_RBS | E11: 1007 | F11: KkStB 4.0 | G11: https://de.wikipedia.org/wiki/KkStB_4 | H11: =AND(CONTROL[[#This Row],[IS_WAGON_OR_COACH]]=TRUE,OR(RIGHT(CONTROL[[#This Row],[VEHIDCODE]],7)="Powered",RIGHT(CONTROL[[#This Row],[VEHIDCODE]],9)="Unpowered")) -> FALSE | I11: =OR(ISNUMBER(SEARCH("_wagon_powered",CONTROL[[#This Row],[VEHIDCODE]])),ISNUMBER(SEARCH("_wagon_unpowered",CONTROL[[#This Row],[VEHIDCODE]])),ISNUMBER(SEARCH("mu_wagon_",CONTROL[[#This Row],[VEHIDCODE]])),ISNUMBER(SEARCH("mglv_wagon_",CONTROL[[#This Row],[VEHIDCODE]])),ISNUMBER(SEARCH("mu_coach_",CONTROL[[#This Row],[VEHIDCODE]])),ISNUMBER(SEARCH("mglv_coach_",CONTROL[[#This Row],[VEHIDCODE]]))) -> FALSE | J11: =ISNUMBER(_xlfn.XMATCH(CONTROL[[#This Row],[VEHIDCODE]],TRACK_TYPES[VEHIDCODE],0)) -> TRUE | K11: =ISNUMBER(_xlfn.XMATCH(CONTROL[[#This Row],[VEHIDCODE]],PROPERTIES[VEHIDCODE],0)) -> TRUE | L11: =ISNUMBER(_xlfn.XLOOKUP(CONTROL[[#This Row],[VEHIDCODE]],roster!A:A,roster!D:D)) -> TRUE | M11: =ISNUMBER(_xlfn.XMATCH(CONTROL[[#This Row],[VEHIDCODE]],GRAPHICS_PROPERTIES[VEHIDCODE],0)) -> TRUE | N11: ="item_"&CONTROL[[#This Row],[VEHIDCODE]] -> item_rbs_KkStB_4_0 | O11: ="str_"&CONTROL[[#This Row],[VEHIDCODE]] -> str_rbs_KkStB_4_0 | P11: =_xlfn.XLOOKUP(CONTROL[[#This Row],[VEHIDCODE]],PROPERTIES[VEHIDCODE],PROPERTIES[IS_CONCEPT])="IS_CONCEPT" -> FALSE | Q11: =_xlfn.XLOOKUP(CONTROL[[#This Row],[VEHIDCODE]],PROPERTIES[VEHIDCODE],PROPERTIES[EXCLUDE]) -> FALSE | R11: {=_xlfn.XLOOKUP(CONTROL[[#This Row],[VEHIDCODE]],GRAPHICS_PROPERTIES[VEHIDCODE],GRAPHICS_PROPERTIES[TEMPLATE_ID]&GRAPHICS_PROPERTIES[TEMPLATE_AMENDMENT_CODE])} -> TPL_03C
A12: rbd_AEC_railmotor_RM1 | B12: =_xlfn.TEXTAFTER(CONTROL[[#This Row],[VEHIDCODE]],"_") -> AEC_railmotor_RM1 | C12: {="src\"&(_xlfn.LET(_xlpm.l,SUBSTITUTE(CONTROL[[#This Row],[VEHID_ID_CATEGORY]],"ID_RANGE_",""),_xlfn.IFS( _xlpm.l="RBS","Railbus\Railbus_Steam", _xlpm.l="RBD","Railbus\Railbus_Diesel", _xlpm.l="RBE","Railbus\Railbus_Electric", _xlpm.l="RBM","Railbus\Railbus_Maglev", _xlpm.l="STEAM","Steam", _xlpm.l="DIESEL","Diesel", OR(_xlpm.l="ELECTRIC", _xlpm.l="MULTIMETRO"),"Electric", _xlpm.l="MAGLEV","Maglev", _xlpm.l="MULTIMAGLEV","MMU", _xlpm.l="CARGODMU","CargoDMU", _xlpm.l="DMU","DMU", _xlpm.l="CARGOEMU","CargoEMU", _xlpm.l="EMU","EMU", _xlpm.l="MMU","MMU", _xlpm.l="SINGLEMETRO","Single_Metro", OR(ISNUMBER(SEARCH("_powered",CONTROL[[#This Row],[VEHIDCODE]])),ISNUMBER(SEARCH("_unpowered",CONTROL[[#This Row],[VEHIDCODE]]))),"Special", _xlpm.l="WAGONS","wagons\"&SUBSTITUTE(_xlfn.TEXTBEFORE(SUBSTITUTE(_xlfn.TEXTAFTER(CONTROL[[#This Row],[VEHIDCODE]],"_",2),"Service_Car","Service#Car"),"_"),"#","_"), _xlpm.l="WAGONS_MGLV","Wagons_Maglev\"&_xlfn.TEXTBEFORE(_xlfn.TEXTAFTER(CONTROL[[#This Row],[VEHIDCODE]],"_",2),"_"), _xlpm.l="COACHES","Coaches\"&_xlfn.TEXTBEFORE(_xlfn.TEXTAFTER(CONTROL[[#This Row],[VEHIDCODE]],"_",2),"_"), _xlpm.l="COACHES_MGLV","Coaches_Maglev\"&_xlfn.TEXTBEFORE(_xlfn.TEXTAFTER(CONTROL[[#This Row],[VEHIDCODE]],"_",2),"_") )))} -> src\Railbus\Railbus_Diesel | D12: {="ID_RANGE_"&_xlfn.IFS( ISNUMBER(SEARCH("mglv_maglev_wagon",CONTROL[[#This Row],[VEHIDCODE]])),"UNIT_WAGONS_MGLV", ISNUMBER(SEARCH("mu_mu_cargo_wagon",CONTROL[[#This Row],[VEHIDCODE]])),"UNIT_WAGONS_RAIL_CARGO", ISNUMBER(SEARCH("mtro_metro_wagon_",CONTROL[[#This Row],[VEHIDCODE]])),"UNIT_WAGONS_MTRO", ISNUMBER(SEARCH("mu_mu_wagon",CONTROL[[#This Row],[VEHIDCODE]])),"UNIT_WAGONS_RAIL", ISNUMBER(SEARCH("mu_wagon",CONTROL[[#This Row],[VEHIDCODE]])),"WAGONS", ISNUMBER(SEARCH("mu_coach",CONTROL[[#This Row],[VEHIDCODE]])),"COACHES", ISNUMBER(SEARCH("mglv_coach",CONTROL[[#This Row],[VEHIDCODE]])),"COACHES_MGLV", _xlfn.TEXTBEFORE(CONTROL[[#This Row],[VEHIDCODE]],"_")="rbs","RBS", _xlfn.TEXTBEFORE(CONTROL[[#This Row],[VEHIDCODE]],"_")="rbd","RBD", _xlfn.TEXTBEFORE(CONTROL[[#This Row],[VEHIDCODE]],"_")="rbe","RBE", _xlfn.TEXTBEFORE(CONTROL[[#This Row],[VEHIDCODE]],"_")="rbm","RBM", _xlfn.TEXTBEFORE(CONTROL[[#This Row],[VEHIDCODE]],"_")="steam","STEAM", _xlfn.TEXTBEFORE(CONTROL[[#This Row],[VEHIDCODE]],"_")="diesel","DIESEL", _xlfn.TEXTBEFORE(CONTROL[[#This Row],[VEHIDCODE]],"_")="electric","ELECTRIC", _xlfn.TEXTBEFORE(CONTROL[[#This Row],[VEHIDCODE]],"_")="mtro","MULTIMETRO", _xlfn.TEXTBEFORE(CONTROL[[#This Row],[VEHIDCODE]],"_")="singlemtro","SINGLEMETRO", _xlfn.TEXTBEFORE(CONTROL[[#This Row],[VEHIDCODE]],"_")="dmu","DMU", _xlfn.TEXTBEFORE(CONTROL[[#This Row],[VEHIDCODE]],"_")="cargodmu","CARGODMU", _xlfn.TEXTBEFORE(CONTROL[[#This Row],[VEHIDCODE]],"_")="emu","EMU", _xlfn.TEXTBEFORE(CONTROL[[#This Row],[VEHIDCODE]],"_")="cargoemu","CARGOEMU", _xlfn.TEXTBEFORE(CONTROL[[#This Row],[VEHIDCODE]],"_",2)="mglv_Wagon","WAGONS_MGLV", AND(_xlfn.TEXTBEFORE(CONTROL[[#This Row],[VEHIDCODE]],"_",1)="mglv",_xlfn.XLOOKUP(CONTROL[[#This Row],[VEHIDCODE]],PROPERTIES[VEHIDCODE],PROPERTIES[DUAL_HEADED])=0),"MAGLEV", _xlfn.TEXTBEFORE(CONTROL[[#This Row],[VEHIDCODE]],"_")="mmu","MMU")} -> ID_RANGE_RBD | E12: 2000 | F12: AEC Railmotor RM1 | G12: https://en.wikipedia.org/wiki/AEC_railmotor | H12: =AND(CONTROL[[#This Row],[IS_WAGON_OR_COACH]]=TRUE,OR(RIGHT(CONTROL[[#This Row],[VEHIDCODE]],7)="Powered",RIGHT(CONTROL[[#This Row],[VEHIDCODE]],9)="Unpowered")) -> FALSE | I12: =OR(ISNUMBER(SEARCH("_wagon_powered",CONTROL[[#This Row],[VEHIDCODE]])),ISNUMBER(SEARCH("_wagon_unpowered",CONTROL[[#This Row],[VEHIDCODE]])),ISNUMBER(SEARCH("mu_wagon_",CONTROL[[#This Row],[VEHIDCODE]])),ISNUMBER(SEARCH("mglv_wagon_",CONTROL[[#This Row],[VEHIDCODE]])),ISNUMBER(SEARCH("mu_coach_",CONTROL[[#This Row],[VEHIDCODE]])),ISNUMBER(SEARCH("mglv_coach_",CONTROL[[#This Row],[VEHIDCODE]]))) -> FALSE | J12: =ISNUMBER(_xlfn.XMATCH(CONTROL[[#This Row],[VEHIDCODE]],TRACK_TYPES[VEHIDCODE],0)) -> TRUE | K12: =ISNUMBER(_xlfn.XMATCH(CONTROL[[#This Row],[VEHIDCODE]],PROPERTIES[VEHIDCODE],0)) -> TRUE | L12: =ISNUMBER(_xlfn.XLOOKUP(CONTROL[[#This Row],[VEHIDCODE]],roster!A:A,roster!D:D)) -> TRUE | M12: =ISNUMBER(_xlfn.XMATCH(CONTROL[[#This Row],[VEHIDCODE]],GRAPHICS_PROPERTIES[VEHIDCODE],0)) -> TRUE | N12: ="item_"&CONTROL[[#This Row],[VEHIDCODE]] -> item_rbd_AEC_railmotor_RM1 | O12: ="str_"&CONTROL[[#This Row],[VEHIDCODE]] -> str_rbd_AEC_railmotor_RM1 | P12: =_xlfn.XLOOKUP(CONTROL[[#This Row],[VEHIDCODE]],PROPERTIES[VEHIDCODE],PROPERTIES[IS_CONCEPT])="IS_CONCEPT" -> FALSE | Q12: =_xlfn.XLOOKUP(CONTROL[[#This Row],[VEHIDCODE]],PROPERTIES[VEHIDCODE],PROPERTIES[EXCLUDE]) -> FALSE | R12: {=_xlfn.XLOOKUP(CONTROL[[#This Row],[VEHIDCODE]],GRAPHICS_PROPERTIES[VEHIDCODE],GRAPHICS_PROPERTIES[TEMPLATE_ID]&GRAPHICS_PROPERTIES[TEMPLATE_AMENDMENT_CODE])} -> TPL_01B
A13: rbd_VT133_Wismar_Railcar | B13: =_xlfn.TEXTAFTER(CONTROL[[#This Row],[VEHIDCODE]],"_") -> VT133_Wismar_Railcar | C13: {="src\"&(_xlfn.LET(_xlpm.l,SUBSTITUTE(CONTROL[[#This Row],[VEHID_ID_CATEGORY]],"ID_RANGE_",""),_xlfn.IFS( _xlpm.l="RBS","Railbus\Railbus_Steam", _xlpm.l="RBD","Railbus\Railbus_Diesel", _xlpm.l="RBE","Railbus\Railbus_Electric", _xlpm.l="RBM","Railbus\Railbus_Maglev", _xlpm.l="STEAM","Steam", _xlpm.l="DIESEL","Diesel", OR(_xlpm.l="ELECTRIC", _xlpm.l="MULTIMETRO"),"Electric", _xlpm.l="MAGLEV","Maglev", _xlpm.l="MULTIMAGLEV","MMU", _xlpm.l="CARGODMU","CargoDMU", _xlpm.l="DMU","DMU", _xlpm.l="CARGOEMU","CargoEMU", _xlpm.l="EMU","EMU", _xlpm.l="MMU","MMU", _xlpm.l="SINGLEMETRO","Single_Metro", OR(ISNUMBER(SEARCH("_powered",CONTROL[[#This Row],[VEHIDCODE]])),ISNUMBER(SEARCH("_unpowered",CONTROL[[#This Row],[VEHIDCODE]]))),"Special", _xlpm.l="WAGONS","wagons\"&SUBSTITUTE(_xlfn.TEXTBEFORE(SUBSTITUTE(_xlfn.TEXTAFTER(CONTROL[[#This Row],[VEHIDCODE]],"_",2),"Service_Car","Service#Car"),"_"),"#","_"), _xlpm.l="WAGONS_MGLV","Wagons_Maglev\"&_xlfn.TEXTBEFORE(_xlfn.TEXTAFTER(CONTROL[[#This Row],[VEHIDCODE]],"_",2),"_"), _xlpm.l="COACHES","Coaches\"&_xlfn.TEXTBEFORE(_xlfn.TEXTAFTER(CONTROL[[#This Row],[VEHIDCODE]],"_",2),"_"), _xlpm.l="COACHES_MGLV","Coaches_Maglev\"&_xlfn.TEXTBEFORE(_xlfn.TEXTAFTER(CONTROL[[#This Row],[VEHIDCODE]],"_",2),"_") )))} -> src\Railbus\Railbus_Diesel | D13: {="ID_RANGE_"&_xlfn.IFS( ISNUMBER(SEARCH("mglv_maglev_wagon",CONTROL[[#This Row],[VEHIDCODE]])),"UNIT_WAGONS_MGLV", ISNUMBER(SEARCH("mu_mu_cargo_wagon",CONTROL[[#This Row],[VEHIDCODE]])),"UNIT_WAGONS_RAIL_CARGO", ISNUMBER(SEARCH("mtro_metro_wagon_",CONTROL[[#This Row],[VEHIDCODE]])),"UNIT_WAGONS_MTRO", ISNUMBER(SEARCH("mu_mu_wagon",CONTROL[[#This Row],[VEHIDCODE]])),"UNIT_WAGONS_RAIL", ISNUMBER(SEARCH("mu_wagon",CONTROL[[#This Row],[VEHIDCODE]])),"WAGONS", ISNUMBER(SEARCH("mu_coach",CONTROL[[#This Row],[VEHIDCODE]])),"COACHES", ISNUMBER(SEARCH("mglv_coach",CONTROL[[#This Row],[VEHIDCODE]])),"COACHES_MGLV", _xlfn.TEXTBEFORE(CONTROL[[#This Row],[VEHIDCODE]],"_")="rbs","RBS", _xlfn.TEXTBEFORE(CONTROL[[#This Row],[VEHIDCODE]],"_")="rbd","RBD", _xlfn.TEXTBEFORE(CONTROL[[#This Row],[VEHIDCODE]],"_")="rbe","RBE", _xlfn.TEXTBEFORE(CONTROL[[#This Row],[VEHIDCODE]],"_")="rbm","RBM", _xlfn.TEXTBEFORE(CONTROL[[#This Row],[VEHIDCODE]],"_")="steam","STEAM", _xlfn.TEXTBEFORE(CONTROL[[#This Row],[VEHIDCODE]],"_")="diesel","DIESEL", _xlfn.TEXTBEFORE(CONTROL[[#This Row],[VEHIDCODE]],"_")="electric","ELECTRIC", _xlfn.TEXTBEFORE(CONTROL[[#This Row],[VEHIDCODE]],"_")="mtro","MULTIMETRO", _xlfn.TEXTBEFORE(CONTROL[[#This Row],[VEHIDCODE]],"_")="singlemtro","SINGLEMETRO", _xlfn.TEXTBEFORE(CONTROL[[#This Row],[VEHIDCODE]],"_")="dmu","DMU", _xlfn.TEXTBEFORE(CONTROL[[#This Row],[VEHIDCODE]],"_")="cargodmu","CARGODMU", _xlfn.TEXTBEFORE(CONTROL[[#This Row],[VEHIDCODE]],"_")="emu","EMU", _xlfn.TEXTBEFORE(CONTROL[[#This Row],[VEHIDCODE]],"_")="cargoemu","CARGOEMU", _xlfn.TEXTBEFORE(CONTROL[[#This Row],[VEHIDCODE]],"_",2)="mglv_Wagon","WAGONS_MGLV", AND(_xlfn.TEXTBEFORE(CONTROL[[#This Row],[VEHIDCODE]],"_",1)="mglv",_xlfn.XLOOKUP(CONTROL[[#This Row],[VEHIDCODE]],PROPERTIES[VEHIDCODE],PROPERTIES[DUAL_HEADED])=0),"MAGLEV", _xlfn.TEXTBEFORE(CONTROL[[#This Row],[VEHIDCODE]],"_")="mmu","MMU")} -> ID_RANGE_RBD | E13: 2001 | F13: VT133 Wismar Railcar | G13: https://en.wikipedia.org/wiki/Wismar_railbus | H13: =AND(CONTROL[[#This Row],[IS_WAGON_OR_COACH]]=TRUE,OR(RIGHT(CONTROL[[#This Row],[VEHIDCODE]],7)="Powered",RIGHT(CONTROL[[#This Row],[VEHIDCODE]],9)="Unpowered")) -> FALSE | I13: =OR(ISNUMBER(SEARCH("_wagon_powered",CONTROL[[#This Row],[VEHIDCODE]])),ISNUMBER(SEARCH("_wagon_unpowered",CONTROL[[#This Row],[VEHIDCODE]])),ISNUMBER(SEARCH("mu_wagon_",CONTROL[[#This Row],[VEHIDCODE]])),ISNUMBER(SEARCH("mglv_wagon_",CONTROL[[#This Row],[VEHIDCODE]])),ISNUMBER(SEARCH("mu_coach_",CONTROL[[#This Row],[VEHIDCODE]])),ISNUMBER(SEARCH("mglv_coach_",CONTROL[[#This Row],[VEHIDCODE]]))) -> FALSE | J13: =ISNUMBER(_xlfn.XMATCH(CONTROL[[#This Row],[VEHIDCODE]],TRACK_TYPES[VEHIDCODE],0)) -> TRUE | K13: =ISNUMBER(_xlfn.XMATCH(CONTROL[[#This Row],[VEHIDCODE]],PROPERTIES[VEHIDCODE],0)) -> TRUE | L13: =ISNUMBER(_xlfn.XLOOKUP(CONTROL[[#This Row],[VEHIDCODE]],roster!A:A,roster!D:D)) -> TRUE | M13: =ISNUMBER(_xlfn.XMATCH(CONTROL[[#This Row],[VEHIDCODE]],GRAPHICS_PROPERTIES[VEHIDCODE],0)) -> TRUE | N13: ="item_"&CONTROL[[#This Row],[VEHIDCODE]] -> item_rbd_VT133_Wismar_Railcar | O13: ="str_"&CONTROL[[#This Row],[VEHIDCODE]] -> str_rbd_VT133_Wismar_Railcar | P13: =_xlfn.XLOOKUP(CONTROL[[#This Row],[VEHIDCODE]],PROPERTIES[VEHIDCODE],PROPERTIES[IS_CONCEPT])="IS_CONCEPT" -> FALSE | Q13: =_xlfn.XLOOKUP(CONTROL[[#This Row],[VEHIDCODE]],PROPERTIES[VEHIDCODE],PROPERTIES[EXCLUDE]) -> FALSE | R13: {=_xlfn.XLOOKUP(CONTROL[[#This Row],[VEHIDCODE]],GRAPHICS_PROPERTIES[VEHIDCODE],GRAPHICS_PROPERTIES[TEMPLATE_ID]&GRAPHICS_PROPERTIES[TEMPLATE_AMENDMENT_CODE])} -> TPL_01B
